Workbook

Sheet Relatório de Mudanças
A1: RELATÓRIO DE MUDANÇAS: PLANILHA DE FIDELIDADE VULTO+
A2: Limpeza feita em 19/10/2026. Arquivo original: clientes_fidelidade_FINAL_v3. Base de comparação: clientes atualizado.xlsx (enviado pelo usuário).
A4: 1. RESUMO
A5: Antes | B5: 5 abas (Clientes, clientes antigos (NAO APAGAR), Resgates, LEIA ISSO, Plan1), com 2.535 linhas de clientes, formatos misturados, duplicados e contagens desatualizadas.
A6: Depois | B6: 6 abas com função clara: Clientes (cadastro), Resgates (movimentação), Pendências (o que falta resolver), Regras e Parâmetros (regras e faixas), Faltam no outro arquivo (correções para o clientes atualizado) e este relatório.
A7: Clientes | B7: 2.535 linhas → 2.395 clientes únicos (1 linha por CPF).
A8: Resgates sem cliente | B8: 45 casos (R$ 2.350) → 21 casos (R$ 980), todos listados na aba Pendências.
A9: Desconto acima da regra | B9: 420 resgates, R$ 17.795 a mais (identificados, não alterados).
A11: 2. ABA CLIENTES
A12: Colunas | B12: Padronizadas e renomeadas: Nome, CPF, CPF válido, E-mail, Telefone, Data Cadastro, Loja Cadastro, Pontos (até 01/01/2025), Categoria, Aceita Msg, Obs, Pendências.
A13: CPF | B13: Todos no formato 000.000.000-00, guardados como texto. Os CPFs que tinham perdido o zero da frente (9 ou 10 dígitos) foram completados com zeros. Nova coluna 'CPF válido' confere os dígitos verificadores (23 continuam inválidos e estão marcados).
A14: Duplicados | B14: 131 CPFs apareciam em 2 ou 3 linhas (271 linhas). DECISÃO DO USUÁRIO: juntar em 1 linha, SOMANDO os pontos, mantendo a data de cadastro mais antiga e o contato mais recente. As linhas de origem ficaram anotadas na coluna Obs.
A15: Nomes e e-mails | B15: Espaços sobrando removidos, nomes com inicial maiúscula, e-mails em minúsculas. E-mails vazios, '-' ou 'nao tem' viraram vazio e foram marcados 'Sem e-mail' (18).
A16: Telefone | B16: Padronizado como (DD) 99999-9999 (o +55 foi tirado). 66 DDDs foram completados com a planilha de atendimentos (WhatsApp/Insta), só quando os 9 dígitos finais eram idênticos; 10 deles ficaram marcados para conferir porque só o telefone bateu. 319 continuam sem DDD (não completei pela loja, porque seria um chute).
A17: Data Cadastro | B17: Convertida para data (dd/mm/aaaa). As datas vinham em vários formatos (dd/mm/aaaa, aaaa-mm-dd, número de série, 'jun/21'). As que só tinham mês e ano (198) ficaram no dia 1 do mês e foram marcadas 'Data aproximada'.
A18: Loja Cadastro | B18: Nomes unificados: Site (site, ecommerce), App, Pinheiros, Eldorado (eldorado shop), Savassi (bh), Batel (CWB).
A19: Pontos | B19: Convertidos para número ('2.203', '1389 pts', '15000 pts'). Valores como '2,7k' viraram 2700 e foram marcados 'Pontos aproximados' (96).
A20: Pontos pós-2025 | B20: DECISÃO DO USUÁRIO: a coluna de pontos foi congelada em 01/01/2025 (regra do LEIA ISSO). Quem se cadastrou depois tem 0 pontos aqui e está marcado 'Pontos no sistema' (894), porque o saldo real está no vulto.db. 26 recadastros pós-2025 também tiveram os pontos zerados.
A21: Categoria | B21: DECISÃO DO USUÁRIO: usar a regra do arquivo 'clientes atualizado' (Bronze 1–1500, Prata 1501–5000, Ouro 5001–9999, Vip 10000+, vazio para 0 pontos), em vez da regra antiga do LEIA ISSO. Virou uma FÓRMULA ligada à tabela de faixas (muda sozinha se a faixa mudar). Antes era digitada à mão (bronze, BRONZE, brz, Silver, Gold, ouro ★, vip?...).
A22: Aceita Msg | B22: 8 formas diferentes (sim, S, 1, x, nao, N, 0, vazio) viraram Sim / Não / Não informado. Não informado deve ser tratado como NÃO (LGPD).
A23: Pendências | B23: Nova coluna que lista o que precisa conferir em cada cliente. Use o filtro dela.
A25: 3. ABA RESGATES
A26: Colunas | B26: Data, CPF, Nome do cliente (fórmula que busca pelo CPF), Pontos usados, Desconto lançado, Desconto pela regra (fórmula), Diferença, Loja, Atendente, Cliente (como anotado), Pendências.
A27: Datas e valores | B27: Datas em 5 formatos foram convertidas para data. Pontos ('1.000') e descontos ('R$ 50,0') que estavam como texto viraram número.
A28: Cliente | B28: Antes a coluna misturava CPF e nome (às vezes só o primeiro nome). Agora tem uma coluna CPF (padronizada) e a anotação original foi mantida em 'Cliente (como anotado)', para ninguém perder a informação.
A29: Identificação | B29: Dos 45 resgates sem cliente identificado, 24 foram resolvidos: nome completo único no cadastro, CPF com erro de digitação corrigido e cruzamento com a planilha de atendimentos (ex.: Luan, linha 413, pelo telefone).
A30: Sem cliente | B30: DECISÃO: os 21 restantes NÃO foram apagados. O desconto foi dado de verdade, e apagar só esconderia o problema (e o saldo de algum cliente pode estar errado). Ficam em amarelo, e 12 deles têm sugestão de cliente para a loja confirmar.
A31: Atendentes | B31: Nomes unificados (ex.: Thiago/tiago/THIAGO → Thiago; carlos.savassi → Carlos; jess.eldorado/jessica → Jéssica).
A32: Taxa de resgate | B32: Nova coluna 'Desconto pela regra' calcula pela taxa da data: R$ 10 por 100 pontos até fev/2025 e R$ 5 desde mar/2025. A coluna Diferença fica em VERMELHO quando o desconto lançado é maior que o da regra.
A34: 4. ACHADO IMPORTANTE: DESCONTO EM DOBRO
A35: O quê | B35: 420 resgates feitos desde mar/2025 foram calculados com a taxa antiga (R$ 10 em vez de R$ 5): R$ 17.795 de desconto a mais.
A36: Padrão | B36: TODOS os 420 são resgates sem atendente anotado, e todos com exatamente o dobro do valor. Nenhum resgate com atendente está errado. No Site, 100% estão errados; nas lojas, de 62% a 75%. O erro acontece todo mês até hoje.
A37: Conclusão | B37: Provável lançamento automático ou em lote (Site/integração) com a taxa antiga configurada. Não é erro das atendentes.
A38: DECISÃO | B38: Os valores NÃO foram alterados (o desconto já saiu). Fica para a empresa conferir no sistema e corrigir a configuração. O resumo por loja e por atendente está na aba Pendências (coluna Q em diante).
A40: 5. ABAS APAGADAS OU JUNTADAS (com autorização do usuário)
A41: Plan1 | B41: Apagada. Tinha contagens de categoria digitadas e desatualizadas (Bronze 300, Prata 140...). Foi substituída pelo resumo automático na aba Regras e Parâmetros.
A42: LEIA ISSO | B42: O texto foi levado para a aba Regras e Parâmetros (coluna E) e atualizado com as novas regras (taxa, categoria, LGPD, como usar a planilha).
A43: clientes antigos | B43: Apagada (programa de 2023, já migrado em jan/24). Antes, aproveitei o que importava: 31 clientes 'Ativo' que não foram migrados estão na aba Pendências (coluna K), e 29 clientes atuais que estavam 'Bloqueado' no programa antigo ganharam esse aviso na coluna Obs.
A44: Backups | B44: As cópias de segurança criadas durante a limpeza foram apagadas no fim. ⚠ Não dá para desfazer pela planilha: guarde o arquivo original se precisar consultar.
A46: 6. ABAS NOVAS
...

Sheet Clientes
A1: Nome | B1: CPF | C1: CPF válido | D1: E-mail | E1: Telefone | F1: Data Cadastro | G1: Loja Cadastro | H1: Pontos (até 01/01/2025) | I1: Categoria | J1: Aceita Msg | K1: Obs | L1: Pendências
A2: Alexandre Almeida Ribeiro | B2: 166.438.408-13 | C2: Sim | D2: alexandre.ribeiro28@yahoo.com.br | E2: 94371-6949 | F2: 44590 | G2: App | H2: 3638 | I2: =IF(H2<=0,"",LOOKUP(H2,'Regras e Parâmetros'!$B$4:$B$7,'Regras e Parâmetros'!$A$4:$A$7)) -> Prata | J2: Não informado | K2: Estava BLOQUEADO no programa antigo | L2: Telefone sem DDD
A3: Alexandre Batista | B3: 874.391.558-23 | C3: Sim | D3: alexandre.batista70@hotmail.com | E3: (41) 90723-3343 | F3: 44967 | G3: Batel | H3: 3321 | I3: =IF(H3<=0,"",LOOKUP(H3,'Regras e Parâmetros'!$B$4:$B$7,'Regras e Parâmetros'!$A$4:$A$7)) -> Prata | J3: Não informado
A4: Alexandre C. Alves | B4: 162.219.500-07 | C4: Sim | D4: alexandre.alves36@outlook.com | E4: 93581-6538 | F4: 45601 | G4: Pinheiros | H4: 75 | I4: =IF(H4<=0,"",LOOKUP(H4,'Regras e Parâmetros'!$B$4:$B$7,'Regras e Parâmetros'!$A$4:$A$7)) -> Bronze | J4: Não | L4: Telefone sem DDD
A5: Alexandre Cardoso | B5: 090.516.597-76 | C5: Sim | D5: alexandre504@gmail.com | E5: (41) 93307-2553 | F5: 45585 | G5: Batel | H5: 294 | I5: =IF(H5<=0,"",LOOKUP(H5,'Regras e Parâmetros'!$B$4:$B$7,'Regras e Parâmetros'!$A$4:$A$7)) -> Bronze | J5: Não informado | K5: Cadastro unificado (2 linhas: 1460, 2427) | Outros e-mails: alexandre.cardoso32@gmial.com | L5: Pontos de recadastro pós-2025 zerados
A6: Alexandre Correia | B6: 503.752.048-73 | C6: Sim | D6: alexandre.correia27@hotmail.com | E6: (85) 91904-3605 | F6: 45682 | G6: Site | H6: 0 | I6: =IF(H6<=0,"",LOOKUP(H6,'Regras e Parâmetros'!$B$4:$B$7,'Regras e Parâmetros'!$A$4:$A$7)) | J6: Sim | K6: aniversario em maio | L6: Pontos no sistema (cadastro após 01/01/2025)
A7: Alexandre Costa | B7: 615.278.307-05 | C7: Sim | D7: alexandre.costa92@icloud.com | E7: (11) 96608-7877 | F7: 46059 | G7: Pinheiros | H7: 0 | I7: =IF(H7<=0,"",LOOKUP(H7,'Regras e Parâmetros'!$B$4:$B$7,'Regras e Parâmetros'!$A$4:$A$7)) | J7: Sim | K7: cliente reclamou | L7: Pontos no sistema (cadastro após 01/01/2025)
A8: Alexandre Fernandes | B8: 140.620.046-82 | C8: Sim | D8: alexandre.fernandes83@icloud.com | E8: (11) 94054-8828 | F8: 45558 | G8: Eldorado | H8: 785 | I8: =IF(H8<=0,"",LOOKUP(H8,'Regras e Parâmetros'!$B$4:$B$7,'Regras e Parâmetros'!$A$4:$A$7)) -> Bronze | J8: Sim
A9: Alexandre Ferreira Araújo | B9: 605.917.487-62 | C9: Sim | D9: alexandre.araujo26@gmail.com | E9: (41) 95110-2094 | F9: 44510 | G9: Batel | H9: 508 | I9: =IF(H9<=0,"",LOOKUP(H9,'Regras e Parâmetros'!$B$4:$B$7,'Regras e Parâmetros'!$A$4:$A$7)) -> Bronze | J9: Não informado | K9: ver com gerente
A10: Alexandre Ferreira Pereira | B10: 785.912.707-54 | C10: Sim | D10: alexandre.pereira62@yahoo.com.br | E10: (11) 98465-0023 | F10: 45379 | G10: Pinheiros | H10: 305 | I10: =IF(H10<=0,"",LOOKUP(H10,'Regras e Parâmetros'!$B$4:$B$7,'Regras e Parâmetros'!$A$4:$A$7)) -> Bronze | J10: Sim
A11: Alexandre Freitas Ramos | B11: 826.620.339-32 | C11: Sim | D11: alexandre.ramos3@hotmail.com | E11: (11) 97561-9899 | F11: 45752 | G11: Pinheiros | H11: 0 | I11: =IF(H11<=0,"",LOOKUP(H11,'Regras e Parâmetros'!$B$4:$B$7,'Regras e Parâmetros'!$A$4:$A$7)) | J11: Não | L11: Pontos no sistema (cadastro após 01/01/2025)
A12: Alexandre Gomes | B12: 256.768.897-80 | C12: Sim | D12: alexandre.gomes37@icloud.com | E12: 94673-6967 | F12: 44937 | G12: Site | H12: 3042 | I12: =IF(H12<=0,"",LOOKUP(H12,'Regras e Parâmetros'!$B$4:$B$7,'Regras e Parâmetros'!$A$4:$A$7)) -> Prata | J12: Não informado | L12: Telefone sem DDD
A13: Alexandre Lopes Martins | B13: 420.881.664-32 | C13: Sim | D13: alexandre.martins92@hotmail.com | E13: (85) 99521-0580 | F13: 44624 | G13: App | H13: 884 | I13: =IF(H13<=0,"",LOOKUP(H13,'Regras e Parâmetros'!$B$4:$B$7,'Regras e Parâmetros'!$A$4:$A$7)) -> Bronze | J13: Não informado
A14: Alexandre Machado Almeida | B14: 406.037.566-70 | C14: Sim | D14: alexandre.almeida3@hotmail.com | E14: (41) 90244-7822 | F14: 46051 | G14: Site | H14: 0 | I14: =IF(H14<=0,"",LOOKUP(H14,'Regras e Parâmetros'!$B$4:$B$7,'Regras e Parâmetros'!$A$4:$A$7)) | J14: Não informado | L14: Pontos no sistema (cadastro após 01/01/2025)
A15: Alexandre Machado Cavalcanti | B15: 569.416.793-79 | C15: Sim | D15: alexandre.cavalcanti5@outlook.com | E15: (11) 90279-6820 | F15: 45614 | G15: Eldorado | H15: 135 | I15: =IF(H15<=0,"",LOOKUP(H15,'Regras e Parâmetros'!$B$4:$B$7,'Regras e Parâmetros'!$A$4:$A$7)) -> Bronze | J15: Não informado | K15: ver com gerente
A16: Alexandre Moreira Fonseca | B16: 250.088.560-73 | C16: Sim | E16: (11) 95372-9822 | F16: 45444 | G16: Eldorado | H16: 0 | I16: =IF(H16<=0,"",LOOKUP(H16,'Regras e Parâmetros'!$B$4:$B$7,'Regras e Parâmetros'!$A$4:$A$7)) | J16: Não informado | L16: Sem e-mail
A17: Alexandre Oliveira | B17: 291.910.183-82 | C17: Sim | D17: alexandre.oliveira15@gmial.com | E17: (31) 99866-0683 | F17: 44746 | G17: Savassi | H17: 1423 | I17: =IF(H17<=0,"",LOOKUP(H17,'Regras e Parâmetros'!$B$4:$B$7,'Regras e Parâmetros'!$A$4:$A$7)) -> Bronze | J17: Não informado | K17: aniversario em maio
A18: Alexandre Ribeiro | B18: 002.747.357-09 | C18: Sim | D18: alexandre.ribeiro51@hotmail.com | E18: (11) 94003-6688 | F18: 45121 | G18: Eldorado | H18: 1000 | I18: =IF(H18<=0,"",LOOKUP(H18,'Regras e Parâmetros'!$B$4:$B$7,'Regras e Parâmetros'!$A$4:$A$7)) -> Bronze | J18: Não | L18: Pontos aproximados (ex.: 2,7k)
A19: Alexandre Rocha Mendes | B19: 140.521.881-95 | C19: Sim | D19: alexandre.mendes92@hotmail.com | E19: (31) 97970-9642 | F19: 45425 | G19: Site | H19: 972 | I19: =IF(H19<=0,"",LOOKUP(H19,'Regras e Parâmetros'!$B$4:$B$7,'Regras e Parâmetros'!$A$4:$A$7)) -> Bronze | J19: Não informado | K19: cliente reclamou
A20: Alexandre Tavares | B20: 105.288.691-40 | C20: Sim | D20: alexandre.tavares50@outlook.com | E20: 96783-6339 | F20: 45428 | G20: Site | H20: 0 | I20: =IF(H20<=0,"",LOOKUP(H20,'Regras e Parâmetros'!$B$4:$B$7,'Regras e Parâmetros'!$A$4:$A$7)) | J20: Sim | L20: Telefone sem DDD
A21: Alice Andrade | B21: 850.663.524-14 | C21: Sim | D21: alice.andrade63@bol.com.br | E21: (11) 92623-8139 | F21: 45834 | G21: Eldorado | H21: 0 | I21: =IF(H21<=0,"",LOOKUP(H21,'Regras e Parâmetros'!$B$4:$B$7,'Regras e Parâmetros'!$A$4:$A$7)) | J21: Não | L21: Pontos no sistema (cadastro após 01/01/2025)
A22: Alice Andrade Dias | B22: 925.262.202-03 | C22: Sim | D22: alice.dias2@bol.com.br | E22: (41) 99085-6913 | F22: 45834 | G22: Site | H22: 0 | I22: =IF(H22<=0,"",LOOKUP(H22,'Regras e Parâmetros'!$B$4:$B$7,'Regras e Parâmetros'!$A$4:$A$7)) | J22: Não informado | K22: cliente reclamou | L22: Pontos no sistema (cadastro após 01/01/2025)
A23: Alice Batista Farias | B23: 677.217.774-61 | C23: Sim | D23: alice.farias36@gmail.com | E23: (11) 99997-9423 | F23: 45548 | G23: Site | H23: 88 | I23: =IF(H23<=0,"",LOOKUP(H23,'Regras e Parâmetros'!$B$4:$B$7,'Regras e Parâmetros'!$A$4:$A$7)) -> Bronze | J23: Não | K23: não ligar
A24: Alice C. Machado | B24: 447.502.186-34 | C24: Sim | D24: alice.machado83@uol.com.br | E24: (41) 98741-0686 | F24: 45413 | G24: Batel | H24: 200 | I24: =IF(H24<=0,"",LOOKUP(H24,'Regras e Parâmetros'!$B$4:$B$7,'Regras e Parâmetros'!$A$4:$A$7)) -> Bronze | J24: Não informado | L24: Data aproximada (só mês/ano)
A25: Alice Cardoso Alves | B25: 105.916.969-08 | C25: Sim | D25: alice.alves72@gmail.com | E25: (21) 96526-5164 | F25: 45191 | G25: App | H25: 97 | I25: =IF(H25<=0,"",LOOKUP(H25,'Regras e Parâmetros'!$B$4:$B$7,'Regras e Parâmetros'!$A$4:$A$7)) -> Bronze | J25: Sim
A26: Alice Correia | B26: 485.479.084-98 | C26: Sim | D26: alice.correia3@hotmail.com | E26: (41) 99478-3236 | F26: 44926 | G26: App | H26: 1823 | I26: =IF(H26<=0,"",LOOKUP(H26,'Regras e Parâmetros'!$B$4:$B$7,'Regras e Parâmetros'!$A$4:$A$7)) -> Prata | J26: Não
A27: Alice Correia | B27: 783.626.843-80 | C27: Sim | D27: alice.correia105@hotmail.com | E27: (31) 97092-2008 | F27: 45261 | G27: Savassi | H27: 1414 | I27: =IF(H27<=0,"",LOOKUP(H27,'Regras e Parâmetros'!$B$4:$B$7,'Regras e Parâmetros'!$A$4:$A$7)) -> Bronze | J27: Sim | K27: Cadastro unificado (2 linhas: 1135, 1435) | Outros e-mails: alice.correia10@hotmail.com | L27: Data aproximada (só mês/ano)
A28: Alice D. Rodrigues | B28: 893.877.273-00 | C28: Sim | D28: alice.rodrigues25@gmail.com | E28: (31) 96413-5345 | F28: 44800 | G28: Savassi | H28: 5717 | I28: =IF(H28<=0,"",LOOKUP(H28,'Regras e Parâmetros'!$B$4:$B$7,'Regras e Parâmetros'!$A$4:$A$7)) -> Ouro | J28: Não informado
A29: Alice Dias Ferreira | B29: 397.719.945-57 | C29: Sim | D29: alice.ferreira76@gmail.com | E29: 91490-7638 | F29: 45865 | G29: App | H29: 0 | I29: =IF(H29<=0,"",LOOKUP(H29,'Regras e Parâmetros'!$B$4:$B$7,'Regras e Parâmetros'!$A$4:$A$7)) | J29: Sim | L29: Pontos no sistema (cadastro após 01/01/2025) | Telefone sem DDD
A30: Alice Ferreira Ribeiro | B30: 001.973.032-26 | C30: Sim | D30: alice.ribeiro87@outlook.com | E30: (11) 97259-2263 | F30: 45444 | G30: App | H30: 5596 | I30: =IF(H30<=0,"",LOOKUP(H30,'Regras e Parâmetros'!$B$4:$B$7,'Regras e Parâmetros'!$A$4:$A$7)) -> Ouro | J30: Não
A31: Alice Fonseca | B31: 941.377.422-60 | C31: Sim | D31: alice.fonseca86@icloud.com | E31: (62) 91890-9061 | F31: 44845 | G31: Site | H31: 1123 | I31: =IF(H31<=0,"",LOOKUP(H31,'Regras e Parâmetros'!$B$4:$B$7,'Regras e Parâmetros'!$A$4:$A$7)) -> Bronze | J31: Sim | K31: não ligar
A32: Alice Gomes | B32: 627.532.074-53 | C32: Sim | D32: alice.gomes14@uol.com.br | E32: (31) 92897-6385 | F32: 45382 | G32: Savassi | H32: 2700 | I32: =IF(H32<=0,"",LOOKUP(H32,'Regras e Parâmetros'!$B$4:$B$7,'Regras e Parâmetros'!$A$4:$A$7)) -> Prata | J32: Não | K32: aniversario em maio | L32: Pontos aproximados (ex.: 2,7k)
A33: Alice Marques Correia | B33: 713.929.904-83 | C33: Sim | D33: alice.correia64@gmail.com | E33: (11) 91527-3444 | F33: 45444 | G33: Pinheiros | H33: 1298 | I33: =IF(H33<=0,"",LOOKUP(H33,'Regras e Parâmetros'!$B$4:$B$7,'Regras e Parâmetros'!$A$4:$A$7)) -> Bronze | J33: Não informado | L33: Data aproximada (só mês/ano)
A34: Alice Marques Teixeira | B34: 868.471.190-47 | C34: Sim | D34: alice.teixeira9@gmail.com | E34: (11) 98823-7237 | F34: 44367 | G34: Pinheiros | H34: 2373 | I34: =IF(H34<=0,"",LOOKUP(H34,'Regras e Parâmetros'!$B$4:$B$7,'Regras e Parâmetros'!$A$4:$A$7)) -> Prata | J34: Sim
A35: Alice Monteiro Moreira | B35: 920.354.730-47 | C35: Sim | D35: alice.moreira16@uol.com.br | E35: (31) 98825-2395 | F35: 44632 | G35: Savassi | H35: 3100 | I35: =IF(H35<=0,"",LOOKUP(H35,'Regras e Parâmetros'!$B$4:$B$7,'Regras e Parâmetros'!$A$4:$A$7)) -> Prata | J35: Sim | L35: Pontos aproximados (ex.: 2,7k)
A36: Alice Moreira Lima | B36: 085.763.295-73 | C36: Sim | D36: alice.lima85@hotmail.com | E36: (11) 94421-2062 | F36: 44621 | G36: Eldorado | H36: 658 | I36: =IF(H36<=0,"",LOOKUP(H36,'Regras e Parâmetros'!$B$4:$B$7,'Regras e Parâmetros'!$A$4:$A$7)) -> Bronze | J36: Não | L36: Data aproximada (só mês/ano)
A37: Alice Moura | B37: 705.054.626-72 | C37: Sim | D37: alice.moura71@yahoo.com.br | E37: (51) 92821-5195 | F37: 45217 | G37: App | H37: 771 | I37: =IF(H37<=0,"",LOOKUP(H37,'Regras e Parâmetros'!$B$4:$B$7,'Regras e Parâmetros'!$A$4:$A$7)) -> Bronze | J37: Não
A38: Alice Nogueira | B38: 888.288.629-80 | C38: Sim | D38: alice.nogueira97@outlook.com | E38: 95302-9297 | F38: 45397 | G38: App | H38: 2712 | I38: =IF(H38<=0,"",LOOKUP(H38,'Regras e Parâmetros'!$B$4:$B$7,'Regras e Parâmetros'!$A$4:$A$7)) -> Prata | J38: Não | L38: Telefone sem DDD
A39: Alice Nogueira | B39: 012.976.285-78 | C39: Sim | D39: alice.nogueira43@outlook.com | E39: 95722-2852 | F39: 45872 | G39: Pinheiros | H39: 0 | I39: =IF(H39<=0,"",LOOKUP(H39,'Regras e Parâmetros'!$B$4:$B$7,'Regras e Parâmetros'!$A$4:$A$7)) | J39: Não informado | K39: CPF corrigido em 19/10/2026 (era 212.976.285-78, inválido; o correto veio dos resgates) | L39: Pontos no sistema (cadastro após 01/01/2025) | Telefone sem DDD
A40: Alice Oliveira Machado | B40: 316.389.963-34 | C40: Sim | D40: alice.machado13@icloud.com | E40: (11) 93748-4445 | F40: 44927 | G40: Eldorado | H40: 1105 | I40: =IF(H40<=0,"",LOOKUP(H40,'Regras e Parâmetros'!$B$4:$B$7,'Regras e Parâmetros'!$A$4:$A$7)) -> Bronze | J40: Não informado | L40: Data aproximada (só mês/ano)
...

Sheet Resgates
A1: Data | B1: CPF | C1: Nome do cliente | D1: Pontos usados | E1: Desconto lançado (R$) | F1: Desconto pela regra (R$) | G1: Diferença (R$) | H1: Loja | I1: Atendente | J1: Cliente (como anotado) | K1: Pendências
A2: 44927 | B2: 908.579.218-51 | C2: =IF(B2="","",IFERROR(INDEX(Clientes!$A:$A,MATCH(B2,Clientes!$B:$B,0)),"(CPF não cadastrado)")) -> Heloísa Nascimento | D2: 1000 | E2: 100 | F2: =D2/100*LOOKUP(A2,'Regras e Parâmetros'!$A$11:$A$12,'Regras e Parâmetros'!$B$11:$B$12) -> 100 | G2: =E2-F2 -> 0 | H2: Eldorado | I2: Carlos | J2: 908.579.218-51 | K2: Data aproximada (só mês/ano)
A3: 44927 | B3: 638.765.788-17 | C3: =IF(B3="","",IFERROR(INDEX(Clientes!$A:$A,MATCH(B3,Clientes!$B:$B,0)),"(CPF não cadastrado)")) -> Sabrina Fonseca Nascimento | D3: 1000 | E3: 100 | F3: =D3/100*LOOKUP(A3,'Regras e Parâmetros'!$A$11:$A$12,'Regras e Parâmetros'!$B$11:$B$12) -> 100 | G3: =E3-F3 -> 0 | H3: Batel | I3: Carlos | J3: 63876578817
A4: 44939 | B4: 638.765.788-17 | C4: =IF(B4="","",IFERROR(INDEX(Clientes!$A:$A,MATCH(B4,Clientes!$B:$B,0)),"(CPF não cadastrado)")) -> Sabrina Fonseca Nascimento | D4: 1000 | E4: 100 | F4: =D4/100*LOOKUP(A4,'Regras e Parâmetros'!$A$11:$A$12,'Regras e Parâmetros'!$B$11:$B$12) -> 100 | G4: =E4-F4 -> 0 | H4: Batel | I4: Carlos | J4: 638.765.788-17
A5: 44947 | B5: 434.741.978-35 | C5: =IF(B5="","",IFERROR(INDEX(Clientes!$A:$A,MATCH(B5,Clientes!$B:$B,0)),"(CPF não cadastrado)")) -> Guilherme Peixoto | D5: 300 | E5: 30 | F5: =D5/100*LOOKUP(A5,'Regras e Parâmetros'!$A$11:$A$12,'Regras e Parâmetros'!$B$11:$B$12) -> 30 | G5: =E5-F5 -> 0 | H5: Batel | I5: Carlos | J5: 43474197835
A6: 44973 | B6: 952.987.358-19 | C6: =IF(B6="","",IFERROR(INDEX(Clientes!$A:$A,MATCH(B6,Clientes!$B:$B,0)),"(CPF não cadastrado)")) -> Eduarda Ramos Cardoso | D6: 1000 | E6: 100 | F6: =D6/100*LOOKUP(A6,'Regras e Parâmetros'!$A$11:$A$12,'Regras e Parâmetros'!$B$11:$B$12) -> 100 | G6: =E6-F6 -> 0 | H6: Eldorado | I6: Carlos | J6: Eduarda Ramos Cardoso | K6: CPF localizado pelo nome
A7: 44982 | B7: 147.527.113-11 | C7: =IF(B7="","",IFERROR(INDEX(Clientes!$A:$A,MATCH(B7,Clientes!$B:$B,0)),"(CPF não cadastrado)")) -> Sofia Freitas | D7: 1000 | E7: 100 | F7: =D7/100*LOOKUP(A7,'Regras e Parâmetros'!$A$11:$A$12,'Regras e Parâmetros'!$B$11:$B$12) -> 100 | G7: =E7-F7 -> 0 | H7: Batel | I7: Carlos | J7: Sofia Freitas | K7: CPF localizado pelo nome
A8: 44986 | B8: 139.616.512-64 | C8: =IF(B8="","",IFERROR(INDEX(Clientes!$A:$A,MATCH(B8,Clientes!$B:$B,0)),"(CPF não cadastrado)")) -> Lívia Araújo Tavares | D8: 200 | E8: 20 | F8: =D8/100*LOOKUP(A8,'Regras e Parâmetros'!$A$11:$A$12,'Regras e Parâmetros'!$B$11:$B$12) -> 20 | G8: =E8-F8 -> 0 | H8: Eldorado | I8: Rafa | J8: 139.616.512-64 | K8: CPF estava certo; o erro era no cadastro (corrigido).
A9: 44989 | B9: 826.562.154-04 | C9: =IF(B9="","",IFERROR(INDEX(Clientes!$A:$A,MATCH(B9,Clientes!$B:$B,0)),"(CPF não cadastrado)")) -> Mariana Rezende | D9: 100 | E9: 10 | F9: =D9/100*LOOKUP(A9,'Regras e Parâmetros'!$A$11:$A$12,'Regras e Parâmetros'!$B$11:$B$12) -> 10 | G9: =E9-F9 -> 0 | H9: Savassi | I9: Bia | J9: 82656215404
A10: 44989 | B10: 428.928.423-01 | C10: =IF(B10="","",IFERROR(INDEX(Clientes!$A:$A,MATCH(B10,Clientes!$B:$B,0)),"(CPF não cadastrado)")) -> Thaís Moura | D10: 200 | E10: 20 | F10: =D10/100*LOOKUP(A10,'Regras e Parâmetros'!$A$11:$A$12,'Regras e Parâmetros'!$B$11:$B$12) -> 20 | G10: =E10-F10 -> 0 | H10: Pinheiros | I10: Carlos | J10: 428.928.423-01
A11: 45000 | B11: 285.089.997-63 | C11: =IF(B11="","",IFERROR(INDEX(Clientes!$A:$A,MATCH(B11,Clientes!$B:$B,0)),"(CPF não cadastrado)")) -> Débora Almeida | D11: 500 | E11: 50 | F11: =D11/100*LOOKUP(A11,'Regras e Parâmetros'!$A$11:$A$12,'Regras e Parâmetros'!$B$11:$B$12) -> 50 | G11: =E11-F11 -> 0 | H11: Savassi | I11: Rafa | J11: 285.089.997-63
A12: 45002 | B12: 036.750.517-73 | C12: =IF(B12="","",IFERROR(INDEX(Clientes!$A:$A,MATCH(B12,Clientes!$B:$B,0)),"(CPF não cadastrado)")) -> Luana Ribeiro Nogueira | D12: 1000 | E12: 100 | F12: =D12/100*LOOKUP(A12,'Regras e Parâmetros'!$A$11:$A$12,'Regras e Parâmetros'!$B$11:$B$12) -> 100 | G12: =E12-F12 -> 0 | H12: Eldorado | J12: Luana Ribeiro Nogueira | K12: CPF localizado pelo nome
A13: 45009 | B13: 151.911.217-32 | C13: =IF(B13="","",IFERROR(INDEX(Clientes!$A:$A,MATCH(B13,Clientes!$B:$B,0)),"(CPF não cadastrado)")) -> Cecília Batista Barros | D13: 500 | E13: 50 | F13: =D13/100*LOOKUP(A13,'Regras e Parâmetros'!$A$11:$A$12,'Regras e Parâmetros'!$B$11:$B$12) -> 50 | G13: =E13-F13 -> 0 | H13: Pinheiros | I13: Rafa | J13: 15191121732
A14: 45016 | C14: =IF(B14="","",IFERROR(INDEX(Clientes!$A:$A,MATCH(B14,Clientes!$B:$B,0)),"(CPF não cadastrado)")) | D14: 300 | E14: 30 | F14: =D14/100*LOOKUP(A14,'Regras e Parâmetros'!$A$11:$A$12,'Regras e Parâmetros'!$B$11:$B$12) -> 30 | G14: =E14-F14 -> 0 | H14: Savassi | I14: Carlos | J14: Nicole Campos Barbosa | K14: Não identificável: nome igual a 2 clientes com CPFs diferentes (830.908.872-82 / 444.089.668-51) – resgate fica sem cliente e fora das pendências
A15: 45019 | C15: =IF(B15="","",IFERROR(INDEX(Clientes!$A:$A,MATCH(B15,Clientes!$B:$B,0)),"(CPF não cadastrado)")) | D15: 300 | E15: 30 | F15: =D15/100*LOOKUP(A15,'Regras e Parâmetros'!$A$11:$A$12,'Regras e Parâmetros'!$B$11:$B$12) -> 30 | G15: =E15-F15 -> 0 | H15: Eldorado | I15: Bia | J15: Rodrigo | K15: Cliente não identificado (só primeiro nome) | Varredura 19/10/2026: sem vendas antes de 2025 no vulto.db para cruzar
A16: 45020 | B16: 445.248.146-98 | C16: =IF(B16="","",IFERROR(INDEX(Clientes!$A:$A,MATCH(B16,Clientes!$B:$B,0)),"(CPF não cadastrado)")) -> Sofia Ferreira | D16: 200 | E16: 20 | F16: =D16/100*LOOKUP(A16,'Regras e Parâmetros'!$A$11:$A$12,'Regras e Parâmetros'!$B$11:$B$12) -> 20 | G16: =E16-F16 -> 0 | H16: Batel | I16: Jéssica | J16: Sofia Ferreira | K16: CPF localizado pelo nome
A17: 45049 | C17: =IF(B17="","",IFERROR(INDEX(Clientes!$A:$A,MATCH(B17,Clientes!$B:$B,0)),"(CPF não cadastrado)")) | D17: 500 | E17: 50 | F17: =D17/100*LOOKUP(A17,'Regras e Parâmetros'!$A$11:$A$12,'Regras e Parâmetros'!$B$11:$B$12) -> 50 | G17: =E17-F17 -> 0 | H17: Eldorado | J17: Luan | K17: Sugestão: Luan Oliveira Gomes 740.762.313-92 (único da loja com DDD; confiança média) | Varredura 19/10/2026: sem vendas antes de 2025 no vulto.db para cruzar
A18: 45056 | B18: 822.480.015-68 | C18: =IF(B18="","",IFERROR(INDEX(Clientes!$A:$A,MATCH(B18,Clientes!$B:$B,0)),"(CPF não cadastrado)")) -> Priscila T. Martins | D18: 100 | E18: 10 | F18: =D18/100*LOOKUP(A18,'Regras e Parâmetros'!$A$11:$A$12,'Regras e Parâmetros'!$B$11:$B$12) -> 10 | G18: =E18-F18 -> 0 | H18: Savassi | I18: Gerente | J18: 82248001568
A19: 45059 | B19: 585.935.177-14 | C19: =IF(B19="","",IFERROR(INDEX(Clientes!$A:$A,MATCH(B19,Clientes!$B:$B,0)),"(CPF não cadastrado)")) -> Davi Ferreira | D19: 300 | E19: 30 | F19: =D19/100*LOOKUP(A19,'Regras e Parâmetros'!$A$11:$A$12,'Regras e Parâmetros'!$B$11:$B$12) -> 30 | G19: =E19-F19 -> 0 | H19: Pinheiros | I19: Carlos | J19: Davi Ferreira | K19: CPF atribuído pela análise (nome repetido: só esta cliente já era cadastrada na data). Confiança alta.
A20: 45075 | B20: 554.320.410-81 | C20: =IF(B20="","",IFERROR(INDEX(Clientes!$A:$A,MATCH(B20,Clientes!$B:$B,0)),"(CPF não cadastrado)")) -> Camila Lima | D20: 100 | E20: 10 | F20: =D20/100*LOOKUP(A20,'Regras e Parâmetros'!$A$11:$A$12,'Regras e Parâmetros'!$B$11:$B$12) -> 10 | G20: =E20-F20 -> 0 | H20: Pinheiros | I20: Gerente | J20: Camila | K20: CPF atribuído pela análise (1º nome: mesma loja, já resgatou lá e DDD). Confiança alta.
A21: 45084 | B21: 383.154.106-01 | C21: =IF(B21="","",IFERROR(INDEX(Clientes!$A:$A,MATCH(B21,Clientes!$B:$B,0)),"(CPF não cadastrado)")) -> Aline Teixeira Nascimento | D21: 200 | E21: 20 | F21: =D21/100*LOOKUP(A21,'Regras e Parâmetros'!$A$11:$A$12,'Regras e Parâmetros'!$B$11:$B$12) -> 20 | G21: =E21-F21 -> 0 | H21: Eldorado | J21: 383.154.106-01
A22: 45109 | B22: 766.120.436-36 | C22: =IF(B22="","",IFERROR(INDEX(Clientes!$A:$A,MATCH(B22,Clientes!$B:$B,0)),"(CPF não cadastrado)")) -> Rafaela Lopes Ramos | D22: 500 | E22: 50 | F22: =D22/100*LOOKUP(A22,'Regras e Parâmetros'!$A$11:$A$12,'Regras e Parâmetros'!$B$11:$B$12) -> 50 | G22: =E22-F22 -> 0 | H22: Batel | I22: Bia | J22: 766.120.436-36
A23: 45118 | B23: 652.493.544-67 | C23: =IF(B23="","",IFERROR(INDEX(Clientes!$A:$A,MATCH(B23,Clientes!$B:$B,0)),"(CPF não cadastrado)")) -> Manuela Ferreira | D23: 500 | E23: 50 | F23: =D23/100*LOOKUP(A23,'Regras e Parâmetros'!$A$11:$A$12,'Regras e Parâmetros'!$B$11:$B$12) -> 50 | G23: =E23-F23 -> 0 | H23: Savassi | I23: Rafa | J23: 652.493.544-67
A24: 45129 | B24: 683.077.020-38 | C24: =IF(B24="","",IFERROR(INDEX(Clientes!$A:$A,MATCH(B24,Clientes!$B:$B,0)),"(CPF não cadastrado)")) -> Paula Rezende | D24: 500 | E24: 50 | F24: =D24/100*LOOKUP(A24,'Regras e Parâmetros'!$A$11:$A$12,'Regras e Parâmetros'!$B$11:$B$12) -> 50 | G24: =E24-F24 -> 0 | H24: Batel | I24: Jéssica | J24: 683.077.020-38
A25: 45133 | B25: 649.567.046-07 | C25: =IF(B25="","",IFERROR(INDEX(Clientes!$A:$A,MATCH(B25,Clientes!$B:$B,0)),"(CPF não cadastrado)")) -> Felipe Monteiro | D25: 1000 | E25: 100 | F25: =D25/100*LOOKUP(A25,'Regras e Parâmetros'!$A$11:$A$12,'Regras e Parâmetros'!$B$11:$B$12) -> 100 | G25: =E25-F25 -> 0 | H25: Batel | I25: Gerente | J25: Felipe | K25: CPF atribuído pela análise (1º nome: mesma loja, já resgatou lá e DDD). Confiança alta.
A26: 45170 | B26: 852.250.131-98 | C26: =IF(B26="","",IFERROR(INDEX(Clientes!$A:$A,MATCH(B26,Clientes!$B:$B,0)),"(CPF não cadastrado)")) -> Juliana Ribeiro Farias | D26: 1000 | E26: 100 | F26: =D26/100*LOOKUP(A26,'Regras e Parâmetros'!$A$11:$A$12,'Regras e Parâmetros'!$B$11:$B$12) -> 100 | G26: =E26-F26 -> 0 | H26: Pinheiros | I26: Gerente | J26: 852.250.131-98 | K26: Data aproximada (só mês/ano)
A27: 45170 | B27: 116.606.891-98 | C27: =IF(B27="","",IFERROR(INDEX(Clientes!$A:$A,MATCH(B27,Clientes!$B:$B,0)),"(CPF não cadastrado)")) -> Emanuelly Pereira Ribeiro | D27: 300 | E27: 30 | F27: =D27/100*LOOKUP(A27,'Regras e Parâmetros'!$A$11:$A$12,'Regras e Parâmetros'!$B$11:$B$12) -> 30 | G27: =E27-F27 -> 0 | H27: Pinheiros | I27: Rafa | J27: Emanuelly Pereira Ribeiro | K27: CPF localizado pelo nome | Data aproximada (só mês/ano)
A28: 45170 | B28: 274.651.585-75 | C28: =IF(B28="","",IFERROR(INDEX(Clientes!$A:$A,MATCH(B28,Clientes!$B:$B,0)),"(CPF não cadastrado)")) -> Daniela Rocha | D28: 200 | E28: 20 | F28: =D28/100*LOOKUP(A28,'Regras e Parâmetros'!$A$11:$A$12,'Regras e Parâmetros'!$B$11:$B$12) -> 20 | G28: =E28-F28 -> 0 | H28: Savassi | I28: Jéssica | J28: Daniela | K28: CPF atribuído pela análise (1º nome: mesma loja, já resgatou lá e DDD). Confiança alta.
A29: 45170 | B29: 409.415.763-88 | C29: =IF(B29="","",IFERROR(INDEX(Clientes!$A:$A,MATCH(B29,Clientes!$B:$B,0)),"(CPF não cadastrado)")) -> Fernanda Campos | D29: 1000 | E29: 100 | F29: =D29/100*LOOKUP(A29,'Regras e Parâmetros'!$A$11:$A$12,'Regras e Parâmetros'!$B$11:$B$12) -> 100 | G29: =E29-F29 -> 0 | H29: Eldorado | I29: Carlos | J29: 40941576388 | K29: Data aproximada (só mês/ano)
A30: 45180 | B30: 110.441.742-18 | C30: =IF(B30="","",IFERROR(INDEX(Clientes!$A:$A,MATCH(B30,Clientes!$B:$B,0)),"(CPF não cadastrado)")) -> Eduarda Ramos | D30: 100 | E30: 10 | F30: =D30/100*LOOKUP(A30,'Regras e Parâmetros'!$A$11:$A$12,'Regras e Parâmetros'!$B$11:$B$12) -> 10 | G30: =E30-F30 -> 0 | H30: Savassi | J30: Eduarda Ramos | K30: CPF localizado pelo nome
A31: 45200 | B31: 588.828.059-30 | C31: =IF(B31="","",IFERROR(INDEX(Clientes!$A:$A,MATCH(B31,Clientes!$B:$B,0)),"(CPF não cadastrado)")) -> Sabrina Campos | D31: 200 | E31: 20 | F31: =D31/100*LOOKUP(A31,'Regras e Parâmetros'!$A$11:$A$12,'Regras e Parâmetros'!$B$11:$B$12) -> 20 | G31: =E31-F31 -> 0 | H31: Eldorado | J31: Sabrina | K31: CPF atribuído pela análise (1º nome: mesma loja, já resgatou lá e DDD). Confiança alta.
A32: 45209 | B32: 103.631.755-20 | C32: =IF(B32="","",IFERROR(INDEX(Clientes!$A:$A,MATCH(B32,Clientes!$B:$B,0)),"(CPF não cadastrado)")) -> Heloísa Campos Nascimento | D32: 1000 | E32: 100 | F32: =D32/100*LOOKUP(A32,'Regras e Parâmetros'!$A$11:$A$12,'Regras e Parâmetros'!$B$11:$B$12) -> 100 | G32: =E32-F32 -> 0 | H32: Savassi | I32: Carlos | J32: 103.631.755-20
A33: 45218 | B33: 339.338.681-65 | C33: =IF(B33="","",IFERROR(INDEX(Clientes!$A:$A,MATCH(B33,Clientes!$B:$B,0)),"(CPF não cadastrado)")) -> Marcelo Rocha | D33: 300 | E33: 30 | F33: =D33/100*LOOKUP(A33,'Regras e Parâmetros'!$A$11:$A$12,'Regras e Parâmetros'!$B$11:$B$12) -> 30 | G33: =E33-F33 -> 0 | H33: Pinheiros | I33: Jéssica | J33: 33933868165
A34: 45239 | B34: 470.492.413-00 | C34: =IF(B34="","",IFERROR(INDEX(Clientes!$A:$A,MATCH(B34,Clientes!$B:$B,0)),"(CPF não cadastrado)")) -> Luana Pinto | D34: 500 | E34: 50 | F34: =D34/100*LOOKUP(A34,'Regras e Parâmetros'!$A$11:$A$12,'Regras e Parâmetros'!$B$11:$B$12) -> 50 | G34: =E34-F34 -> 0 | H34: Eldorado | I34: Jéssica | J34: 47049241300
A35: 45239 | B35: 936.966.479-34 | C35: =IF(B35="","",IFERROR(INDEX(Clientes!$A:$A,MATCH(B35,Clientes!$B:$B,0)),"(CPF não cadastrado)")) -> Juliana Soares | D35: 200 | E35: 20 | F35: =D35/100*LOOKUP(A35,'Regras e Parâmetros'!$A$11:$A$12,'Regras e Parâmetros'!$B$11:$B$12) -> 20 | G35: =E35-F35 -> 0 | H35: Eldorado | I35: Carlos | J35: 93696647934
A36: 45253 | B36: 411.634.979-83 | C36: =IF(B36="","",IFERROR(INDEX(Clientes!$A:$A,MATCH(B36,Clientes!$B:$B,0)),"(CPF não cadastrado)")) -> Henrique Santana | D36: 300 | E36: 30 | F36: =D36/100*LOOKUP(A36,'Regras e Parâmetros'!$A$11:$A$12,'Regras e Parâmetros'!$B$11:$B$12) -> 30 | G36: =E36-F36 -> 0 | H36: Savassi | I36: Bia | J36: Henrique Santana | K36: CPF localizado pelo nome
A37: 45285 | B37: 106.710.169-11 | C37: =IF(B37="","",IFERROR(INDEX(Clientes!$A:$A,MATCH(B37,Clientes!$B:$B,0)),"(CPF não cadastrado)")) -> Rebeca Martins | D37: 200 | E37: 20 | F37: =D37/100*LOOKUP(A37,'Regras e Parâmetros'!$A$11:$A$12,'Regras e Parâmetros'!$B$11:$B$12) -> 20 | G37: =E37-F37 -> 0 | H37: Savassi | J37: 10671016911
A38: 45295 | B38: 572.245.905-41 | C38: =IF(B38="","",IFERROR(INDEX(Clientes!$A:$A,MATCH(B38,Clientes!$B:$B,0)),"(CPF não cadastrado)")) -> Lorena Rodrigues | D38: 500 | E38: 50 | F38: =D38/100*LOOKUP(A38,'Regras e Parâmetros'!$A$11:$A$12,'Regras e Parâmetros'!$B$11:$B$12) -> 50 | G38: =E38-F38 -> 0 | H38: Savassi | I38: Gerente | J38: 57224590541
A39: 45299 | B39: 110.867.188-87 | C39: =IF(B39="","",IFERROR(INDEX(Clientes!$A:$A,MATCH(B39,Clientes!$B:$B,0)),"(CPF não cadastrado)")) -> Rodrigo Nunes | D39: 300 | E39: 30 | F39: =D39/100*LOOKUP(A39,'Regras e Parâmetros'!$A$11:$A$12,'Regras e Parâmetros'!$B$11:$B$12) -> 30 | G39: =E39-F39 -> 0 | H39: Batel | J39: 11086718887
A40: 45305 | B40: 092.742.848-29 | C40: =IF(B40="","",IFERROR(INDEX(Clientes!$A:$A,MATCH(B40,Clientes!$B:$B,0)),"(CPF não cadastrado)")) -> (CPF não cadastrado) | D40: 500 | E40: 50 | F40: =D40/100*LOOKUP(A40,'Regras e Parâmetros'!$A$11:$A$12,'Regras e Parâmetros'!$B$11:$B$12) -> 50 | G40: =E40-F40 -> 0 | H40: Batel | I40: Carlos | J40: 9274284829 | K40: CPF não está no cadastro
...

Sheet Pendências
A1: PENDÊNCIAS PARA CONFERIR
A2: Como resolver: descubra o CPF (com a loja/atendente ou pela venda do dia) e digite na coluna CPF da aba Resgates, na linha indicada. O caso sai desta lista automaticamente.
A3: 1) Resgates sem cliente identificado | K3: 2) Clientes ATIVOS do programa antigo fora da aba Clientes – apenas registro (nada a devolver) | Q3: 3) Descontos dados ACIMA da regra (taxa antiga de R$10 usada depois de mar/2025)
A4: Casos pendentes | B4: =COUNT(INDEX(_xlfn.ANCHORARRAY(A10),0,1)) -> 9 | K4: Clientes | L4: =COUNTA(L10:L40) -> 31 | Q4: Resgates com erro | R4: =COUNTIF(Resgates!$G$2:$G$597,">0") -> 420
A5: Pontos usados | B5: =SUM(INDEX(_xlfn.ANCHORARRAY(A10),0,4)) -> 4200 | K5: Pontos em 2023 | L5: =SUM(M10:M40) -> 112103 | Q5: Desconto a mais (R$) | R5: =SUMIF(Resgates!$G$2:$G$597,">0") -> 17795
A6: Desconto dado (R$) | B6: =SUM(INDEX(_xlfn.ANCHORARRAY(A10),0,5)) -> 370 | Q6: Padrão: TODOS os 420 erros são resgates sem atendente anotado, e todos têm exatamente o dobro do valor. Nenhum resgate com atendente anotado está errado. Provável origem: lançamento automático ou em lote (o Site está 100% errado), ainda calculado com a taxa antiga. Conferir no sistema se o desconto foi realmente dado em dobro ou se só o registro está errado.
A9: Linha na aba Resgates | B9: Data | C9: Cliente (como anotado) | D9: Pontos usados | E9: Desconto lançado (R$) | F9: Loja | G9: Atendente | H9: Motivo | I9: Sugestão / clientes possíveis | J9: Próximo passo (varredura automática) | K9: Nome | L9: CPF | M9: Pontos 2023 | N9: Última compra | O9: Situação | Q9: Loja | R9: Resgates desde mar/25 | S9: Com erro | T9: % com erro | U9: Desconto a mais (R$)
A10: {=_xlfn._xlws.FILTER(_xlfn.HSTACK(ROW(Resgates!A2:A597),Resgates!A2:A597,IF(Resgates!J2:J597="","",Resgates!J2:J597),Resgates!D2:D597,Resgates!E2:E597,Resgates!H2:H597,IF(Resgates!I2:I597="","",Resgates!I2:I597)),((Resgates!C2:C597="")+(Resgates!C2:C597="(CPF não cadastrado)"))*(LEFT(Resgates!K2:K597,17)<>"Não identificável"),"Nenhum caso pendente")} -> 15 | B10: 45019 | C10: Rodrigo | D10: 300 | E10: 30 | F10: Eldorado | G10: Bia | H10: {=IF(NOT(ISNUMBER(A10)),"",IF(INDEX(Resgates!$B:$B,A10)<>"","CPF não está no cadastro",IF(ISNUMBER(SEARCH(" ",TRIM(C10))),IF(COUNTIF(Clientes!$A$2:$A$2396,TRIM(C10))>1,"Nome repetido no cadastro","Nome não encontrado no cadastro"),"Só o primeiro nome")))} -> Só o primeiro nome | I10: {=IF(H10="","",IF(LEFT(INDEX(Resgates!$K:$K,A10),9)="Sugestão:",INDEX(Resgates!$K:$K,A10),IF(H10="Nome repetido no cadastro",_xlfn.TEXTJOIN(" / ",TRUE,_xlfn._xlws.FILTER(Clientes!$A$2:$A$2396&" – "&Clientes!$B$2:$B$2396&" (cadastro "&Clientes!$G$2:$G$2396&")",Clientes!$A$2:$A$2396=TRIM(C10))),IF(H10="Só o primeiro nome",COUNTIF(Clientes!$A$2:$A$2396,TRIM(C10)&" *")&" clientes com esse primeiro nome – confirmar com a loja/atendente",IF(H10="CPF não está no cadastro","Conferir se o CPF foi digitado errado ou se o cliente não foi cadastrado","Confirmar com a loja")))))} -> 30 clientes com esse primeiro nome – confirmar com a loja/atendente | J10: =IF(H10="Só o primeiro nome","Buscar em vendas e atendimentos: primeiro nome """&TRIM(C10)&""" + loja "&F10&" + dia "&TEXT(DAY(B10),"00")&"/"&TEXT(MONTH(B10),"00")&"/"&YEAR(B10)&" (ver aba Varredura)","") -> Buscar em vendas e atendimentos: primeiro nome "Rodrigo" + loja Eldorado + dia 03/04/2023 (ver aba Varredura) | K10: Eduarda Nunes | L10: 366.019.093-43 | M10: 4669 | N10: 45025 | O10: Encerrado: pontos de 2023 já teriam vencido (regra de 12 meses) | Q10: Site | R10: =COUNTIFS(Resgates!$H$2:$H$597,Q10,Resgates!$A$2:$A$597,">="&'Regras e Parâmetros'!$A$12) -> 229 | S10: =COUNTIFS(Resgates!$H$2:$H$597,Q10,Resgates!$G$2:$G$597,">0") -> 229 | T10: =IF(R10=0,0,S10/R10) -> 1 | U10: =SUMIFS(Resgates!$G$2:$G$597,Resgates!$H$2:$H$597,Q10,Resgates!$G$2:$G$597,">0") -> 8555
A11: 17 | B11: 45049 | C11: Luan | D11: 500 | E11: 50 | F11: Eldorado | H11: {=IF(NOT(ISNUMBER(A11)),"",IF(INDEX(Resgates!$B:$B,A11)<>"","CPF não está no cadastro",IF(ISNUMBER(SEARCH(" ",TRIM(C11))),IF(COUNTIF(Clientes!$A$2:$A$2396,TRIM(C11))>1,"Nome repetido no cadastro","Nome não encontrado no cadastro"),"Só o primeiro nome")))} -> Só o primeiro nome | I11: {=IF(H11="","",IF(LEFT(INDEX(Resgates!$K:$K,A11),9)="Sugestão:",INDEX(Resgates!$K:$K,A11),IF(H11="Nome repetido no cadastro",_xlfn.TEXTJOIN(" / ",TRUE,_xlfn._xlws.FILTER(Clientes!$A$2:$A$2396&" – "&Clientes!$B$2:$B$2396&" (cadastro "&Clientes!$G$2:$G$2396&")",Clientes!$A$2:$A$2396=TRIM(C11))),IF(H11="Só o primeiro nome",COUNTIF(Clientes!$A$2:$A$2396,TRIM(C11)&" *")&" clientes com esse primeiro nome – confirmar com a loja/atendente",IF(H11="CPF não está no cadastro","Conferir se o CPF foi digitado errado ou se o cliente não foi cadastrado","Confirmar com a loja")))))} -> Sugestão: Luan Oliveira Gomes 740.762.313-92 (único da loja com DDD; confiança média) | Varredura 19/10/2026: sem vendas antes de 2025 no vulto.db para cruzar | J11: =IF(H11="Só o primeiro nome","Buscar em vendas e atendimentos: primeiro nome """&TRIM(C11)&""" + loja "&F11&" + dia "&TEXT(DAY(B11),"00")&"/"&TEXT(MONTH(B11),"00")&"/"&YEAR(B11)&" (ver aba Varredura)","") -> Buscar em vendas e atendimentos: primeiro nome "Luan" + loja Eldorado + dia 03/05/2023 (ver aba Varredura) | K11: Valentina Correia | L11: 231.639.906-14 | M11: 7659 | N11: 45122 | O11: Encerrado: pontos de 2023 já teriam vencido (regra de 12 meses) | Q11: Eldorado | R11: =COUNTIFS(Resgates!$H$2:$H$597,Q11,Resgates!$A$2:$A$597,">="&'Regras e Parâmetros'!$A$12) -> 72 | S11: =COUNTIFS(Resgates!$H$2:$H$597,Q11,Resgates!$G$2:$G$597,">0") -> 50 | T11: =IF(R11=0,0,S11/R11) -> 0.69444444 | U11: =SUMIFS(Resgates!$G$2:$G$597,Resgates!$H$2:$H$597,Q11,Resgates!$G$2:$G$597,">0") -> 2515
A12: 40 | B12: 45305 | C12: 9274284829 | D12: 500 | E12: 50 | F12: Batel | G12: Carlos | H12: {=IF(NOT(ISNUMBER(A12)),"",IF(INDEX(Resgates!$B:$B,A12)<>"","CPF não está no cadastro",IF(ISNUMBER(SEARCH(" ",TRIM(C12))),IF(COUNTIF(Clientes!$A$2:$A$2396,TRIM(C12))>1,"Nome repetido no cadastro","Nome não encontrado no cadastro"),"Só o primeiro nome")))} -> CPF não está no cadastro | I12: {=IF(H12="","",IF(LEFT(INDEX(Resgates!$K:$K,A12),9)="Sugestão:",INDEX(Resgates!$K:$K,A12),IF(H12="Nome repetido no cadastro",_xlfn.TEXTJOIN(" / ",TRUE,_xlfn._xlws.FILTER(Clientes!$A$2:$A$2396&" – "&Clientes!$B$2:$B$2396&" (cadastro "&Clientes!$G$2:$G$2396&")",Clientes!$A$2:$A$2396=TRIM(C12))),IF(H12="Só o primeiro nome",COUNTIF(Clientes!$A$2:$A$2396,TRIM(C12)&" *")&" clientes com esse primeiro nome – confirmar com a loja/atendente",IF(H12="CPF não está no cadastro","Conferir se o CPF foi digitado errado ou se o cliente não foi cadastrado","Confirmar com a loja")))))} -> Conferir se o CPF foi digitado errado ou se o cliente não foi cadastrado | J12: =IF(H12="Só o primeiro nome","Buscar em vendas e atendimentos: primeiro nome """&TRIM(C12)&""" + loja "&F12&" + dia "&TEXT(DAY(B12),"00")&"/"&TEXT(MONTH(B12),"00")&"/"&YEAR(B12)&" (ver aba Varredura)","") | K12: Manuela Monteiro | L12: 169.217.378-29 | M12: 1778 | N12: 45032 | O12: Encerrado: pontos de 2023 já teriam vencido (regra de 12 meses) | Q12: Pinheiros | R12: =COUNTIFS(Resgates!$H$2:$H$597,Q12,Resgates!$A$2:$A$597,">="&'Regras e Parâmetros'!$A$12) -> 74 | S12: =COUNTIFS(Resgates!$H$2:$H$597,Q12,Resgates!$G$2:$G$597,">0") -> 46 | T12: =IF(R12=0,0,S12/R12) -> 0.62162162 | U12: =SUMIFS(Resgates!$G$2:$G$597,Resgates!$H$2:$H$597,Q12,Resgates!$G$2:$G$597,">0") -> 2410
A13: 53 | B13: 45567 | C13: Juliana | D13: 1000 | E13: 100 | F13: Savassi | H13: {=IF(NOT(ISNUMBER(A13)),"",IF(INDEX(Resgates!$B:$B,A13)<>"","CPF não está no cadastro",IF(ISNUMBER(SEARCH(" ",TRIM(C13))),IF(COUNTIF(Clientes!$A$2:$A$2396,TRIM(C13))>1,"Nome repetido no cadastro","Nome não encontrado no cadastro"),"Só o primeiro nome")))} -> Só o primeiro nome | I13: {=IF(H13="","",IF(LEFT(INDEX(Resgates!$K:$K,A13),9)="Sugestão:",INDEX(Resgates!$K:$K,A13),IF(H13="Nome repetido no cadastro",_xlfn.TEXTJOIN(" / ",TRUE,_xlfn._xlws.FILTER(Clientes!$A$2:$A$2396&" – "&Clientes!$B$2:$B$2396&" (cadastro "&Clientes!$G$2:$G$2396&")",Clientes!$A$2:$A$2396=TRIM(C13))),IF(H13="Só o primeiro nome",COUNTIF(Clientes!$A$2:$A$2396,TRIM(C13)&" *")&" clientes com esse primeiro nome – confirmar com a loja/atendente",IF(H13="CPF não está no cadastro","Conferir se o CPF foi digitado errado ou se o cliente não foi cadastrado","Confirmar com a loja")))))} -> 39 clientes com esse primeiro nome – confirmar com a loja/atendente | J13: =IF(H13="Só o primeiro nome","Buscar em vendas e atendimentos: primeiro nome """&TRIM(C13)&""" + loja "&F13&" + dia "&TEXT(DAY(B13),"00")&"/"&TEXT(MONTH(B13),"00")&"/"&YEAR(B13)&" (ver aba Varredura)","") -> Buscar em vendas e atendimentos: primeiro nome "Juliana" + loja Savassi + dia 02/10/2024 (ver aba Varredura) | K13: Breno Ferreira | L13: 220.402.682-43 | M13: 960 | N13: 45232 | O13: Encerrado: pontos de 2023 já teriam vencido (regra de 12 meses) | Q13: Batel | R13: =COUNTIFS(Resgates!$H$2:$H$597,Q13,Resgates!$A$2:$A$597,">="&'Regras e Parâmetros'!$A$12) -> 71 | S13: =COUNTIFS(Resgates!$H$2:$H$597,Q13,Resgates!$G$2:$G$597,">0") -> 50 | T13: =IF(R13=0,0,S13/R13) -> 0.70422535 | U13: =SUMIFS(Resgates!$G$2:$G$597,Resgates!$H$2:$H$597,Q13,Resgates!$G$2:$G$597,">0") -> 2270
A14: 56 | B14: 45597 | C14: Alexandre | D14: 300 | E14: 30 | F14: Batel | G14: Carlos | H14: {=IF(NOT(ISNUMBER(A14)),"",IF(INDEX(Resgates!$B:$B,A14)<>"","CPF não está no cadastro",IF(ISNUMBER(SEARCH(" ",TRIM(C14))),IF(COUNTIF(Clientes!$A$2:$A$2396,TRIM(C14))>1,"Nome repetido no cadastro","Nome não encontrado no cadastro"),"Só o primeiro nome")))} -> Só o primeiro nome | I14: {=IF(H14="","",IF(LEFT(INDEX(Resgates!$K:$K,A14),9)="Sugestão:",INDEX(Resgates!$K:$K,A14),IF(H14="Nome repetido no cadastro",_xlfn.TEXTJOIN(" / ",TRUE,_xlfn._xlws.FILTER(Clientes!$A$2:$A$2396&" – "&Clientes!$B$2:$B$2396&" (cadastro "&Clientes!$G$2:$G$2396&")",Clientes!$A$2:$A$2396=TRIM(C14))),IF(H14="Só o primeiro nome",COUNTIF(Clientes!$A$2:$A$2396,TRIM(C14)&" *")&" clientes com esse primeiro nome – confirmar com a loja/atendente",IF(H14="CPF não está no cadastro","Conferir se o CPF foi digitado errado ou se o cliente não foi cadastrado","Confirmar com a loja")))))} -> 19 clientes com esse primeiro nome – confirmar com a loja/atendente | J14: =IF(H14="Só o primeiro nome","Buscar em vendas e atendimentos: primeiro nome """&TRIM(C14)&""" + loja "&F14&" + dia "&TEXT(DAY(B14),"00")&"/"&TEXT(MONTH(B14),"00")&"/"&YEAR(B14)&" (ver aba Varredura)","") -> Buscar em vendas e atendimentos: primeiro nome "Alexandre" + loja Batel + dia 01/11/2024 (ver aba Varredura) | K14: Rafaela Soares Barros | L14: 651.539.252-42 | M14: 1542 | N14: 45190 | O14: Encerrado: pontos de 2023 já teriam vencido (regra de 12 meses) | Q14: Savassi | R14: =COUNTIFS(Resgates!$H$2:$H$597,Q14,Resgates!$A$2:$A$597,">="&'Regras e Parâmetros'!$A$12) -> 60 | S14: =COUNTIFS(Resgates!$H$2:$H$597,Q14,Resgates!$G$2:$G$597,">0") -> 45 | T14: =IF(R14=0,0,S14/R14) -> 0.75 | U14: =SUMIFS(Resgates!$G$2:$G$597,Resgates!$H$2:$H$597,Q14,Resgates!$G$2:$G$597,">0") -> 2045
A15: 58 | B15: 45604 | C15: Leonardo | D15: 100 | E15: 10 | F15: Eldorado | G15: Rafa | H15: {=IF(NOT(ISNUMBER(A15)),"",IF(INDEX(Resgates!$B:$B,A15)<>"","CPF não está no cadastro",IF(ISNUMBER(SEARCH(" ",TRIM(C15))),IF(COUNTIF(Clientes!$A$2:$A$2396,TRIM(C15))>1,"Nome repetido no cadastro","Nome não encontrado no cadastro"),"Só o primeiro nome")))} -> Só o primeiro nome | I15: {=IF(H15="","",IF(LEFT(INDEX(Resgates!$K:$K,A15),9)="Sugestão:",INDEX(Resgates!$K:$K,A15),IF(H15="Nome repetido no cadastro",_xlfn.TEXTJOIN(" / ",TRUE,_xlfn._xlws.FILTER(Clientes!$A$2:$A$2396&" – "&Clientes!$B$2:$B$2396&" (cadastro "&Clientes!$G$2:$G$2396&")",Clientes!$A$2:$A$2396=TRIM(C15))),IF(H15="Só o primeiro nome",COUNTIF(Clientes!$A$2:$A$2396,TRIM(C15)&" *")&" clientes com esse primeiro nome – confirmar com a loja/atendente",IF(H15="CPF não está no cadastro","Conferir se o CPF foi digitado errado ou se o cliente não foi cadastrado","Confirmar com a loja")))))} -> 13 clientes com esse primeiro nome – confirmar com a loja/atendente | J15: =IF(H15="Só o primeiro nome","Buscar em vendas e atendimentos: primeiro nome """&TRIM(C15)&""" + loja "&F15&" + dia "&TEXT(DAY(B15),"00")&"/"&TEXT(MONTH(B15),"00")&"/"&YEAR(B15)&" (ver aba Varredura)","") -> Buscar em vendas e atendimentos: primeiro nome "Leonardo" + loja Eldorado + dia 08/11/2024 (ver aba Varredura) | K15: Davi Alves | L15: 983.293.371-46 | M15: 3107 | N15: 45093 | O15: Encerrado: pontos de 2023 já teriam vencido (regra de 12 meses) | Q15: Total | R15: =SUM(R10:R14) -> 506 | S15: =SUM(S10:S14) -> 420 | T15: =IF(R15=0,0,S15/R15) -> 0.83003953 | U15: =SUM(U10:U14) -> 17795
A16: 59 | B16: 45610 | C16: Mariana | D16: 500 | E16: 50 | F16: Batel | H16: {=IF(NOT(ISNUMBER(A16)),"",IF(INDEX(Resgates!$B:$B,A16)<>"","CPF não está no cadastro",IF(ISNUMBER(SEARCH(" ",TRIM(C16))),IF(COUNTIF(Clientes!$A$2:$A$2396,TRIM(C16))>1,"Nome repetido no cadastro","Nome não encontrado no cadastro"),"Só o primeiro nome")))} -> Só o primeiro nome | I16: {=IF(H16="","",IF(LEFT(INDEX(Resgates!$K:$K,A16),9)="Sugestão:",INDEX(Resgates!$K:$K,A16),IF(H16="Nome repetido no cadastro",_xlfn.TEXTJOIN(" / ",TRUE,_xlfn._xlws.FILTER(Clientes!$A$2:$A$2396&" – "&Clientes!$B$2:$B$2396&" (cadastro "&Clientes!$G$2:$G$2396&")",Clientes!$A$2:$A$2396=TRIM(C16))),IF(H16="Só o primeiro nome",COUNTIF(Clientes!$A$2:$A$2396,TRIM(C16)&" *")&" clientes com esse primeiro nome – confirmar com a loja/atendente",IF(H16="CPF não está no cadastro","Conferir se o CPF foi digitado errado ou se o cliente não foi cadastrado","Confirmar com a loja")))))} -> Sugestão: Mariana Marques 142.255.830-40 (única da loja com DDD; confiança média) | Varredura 19/10/2026: sem vendas antes de 2025 no vulto.db para cruzar | J16: =IF(H16="Só o primeiro nome","Buscar em vendas e atendimentos: primeiro nome """&TRIM(C16)&""" + loja "&F16&" + dia "&TEXT(DAY(B16),"00")&"/"&TEXT(MONTH(B16),"00")&"/"&YEAR(B16)&" (ver aba Varredura)","") -> Buscar em vendas e atendimentos: primeiro nome "Mariana" + loja Batel + dia 14/11/2024 (ver aba Varredura) | K16: Giovanna Almeida Pinto | L16: 300.105.589-85 | M16: 5526 | N16: 45001 | O16: Encerrado: pontos de 2023 já teriam vencido (regra de 12 meses)
A17: 554 | B17: 46245 | C17: Júlia | D17: 500 | E17: 25 | F17: Savassi | G17: Ana Paula | H17: {=IF(NOT(ISNUMBER(A17)),"",IF(INDEX(Resgates!$B:$B,A17)<>"","CPF não está no cadastro",IF(ISNUMBER(SEARCH(" ",TRIM(C17))),IF(COUNTIF(Clientes!$A$2:$A$2396,TRIM(C17))>1,"Nome repetido no cadastro","Nome não encontrado no cadastro"),"Só o primeiro nome")))} -> Só o primeiro nome | I17: {=IF(H17="","",IF(LEFT(INDEX(Resgates!$K:$K,A17),9)="Sugestão:",INDEX(Resgates!$K:$K,A17),IF(H17="Nome repetido no cadastro",_xlfn.TEXTJOIN(" / ",TRUE,_xlfn._xlws.FILTER(Clientes!$A$2:$A$2396&" – "&Clientes!$B$2:$B$2396&" (cadastro "&Clientes!$G$2:$G$2396&")",Clientes!$A$2:$A$2396=TRIM(C17))),IF(H17="Só o primeiro nome",COUNTIF(Clientes!$A$2:$A$2396,TRIM(C17)&" *")&" clientes com esse primeiro nome – confirmar com a loja/atendente",IF(H17="CPF não está no cadastro","Conferir se o CPF foi digitado errado ou se o cliente não foi cadastrado","Confirmar com a loja")))))} -> Sugestão: Julia Fernandes 558.971.099-58 (única venda do dia na loja com esse nome, venda 17215, mas o desconto foi R$ 33,00 e o resgate anotado é R$ 25,00) ou Júlia Peixoto Ferreira 123.214.834-23 (cadastro na Savassi + atendimento de 16/08/2026 com o mesmo nome; confiança média-alta); confirmar com a loja | J17: =IF(H17="Só o primeiro nome","Buscar em vendas e atendimentos: primeiro nome """&TRIM(C17)&""" + loja "&F17&" + dia "&TEXT(DAY(B17),"00")&"/"&TEXT(MONTH(B17),"00")&"/"&YEAR(B17)&" (ver aba Varredura)","") -> Buscar em vendas e atendimentos: primeiro nome "Júlia" + loja Savassi + dia 11/08/2026 (ver aba Varredura) | K17: Rebeca Soares | L17: 507.766.382-38 | M17: 7240 | N17: 44949 | O17: Encerrado: pontos de 2023 já teriam vencido (regra de 12 meses)
A18: 582 | B18: 46281 | C18: João | D18: 500 | E18: 25 | F18: Eldorado | G18: Thiago | H18: {=IF(NOT(ISNUMBER(A18)),"",IF(INDEX(Resgates!$B:$B,A18)<>"","CPF não está no cadastro",IF(ISNUMBER(SEARCH(" ",TRIM(C18))),IF(COUNTIF(Clientes!$A$2:$A$2396,TRIM(C18))>1,"Nome repetido no cadastro","Nome não encontrado no cadastro"),"Só o primeiro nome")))} -> Só o primeiro nome | I18: {=IF(H18="","",IF(LEFT(INDEX(Resgates!$K:$K,A18),9)="Sugestão:",INDEX(Resgates!$K:$K,A18),IF(H18="Nome repetido no cadastro",_xlfn.TEXTJOIN(" / ",TRUE,_xlfn._xlws.FILTER(Clientes!$A$2:$A$2396&" – "&Clientes!$B$2:$B$2396&" (cadastro "&Clientes!$G$2:$G$2396&")",Clientes!$A$2:$A$2396=TRIM(C18))),IF(H18="Só o primeiro nome",COUNTIF(Clientes!$A$2:$A$2396,TRIM(C18)&" *")&" clientes com esse primeiro nome – confirmar com a loja/atendente",IF(H18="CPF não está no cadastro","Conferir se o CPF foi digitado errado ou se o cliente não foi cadastrado","Confirmar com a loja")))))} -> Sugestão: João Pereira Mendes 249.952.721-86 (único da loja; confiança média) | Varredura 19/10/2026: nenhuma venda de cliente com esse nome na loja de 15 a 17/09/2026 | J18: =IF(H18="Só o primeiro nome","Buscar em vendas e atendimentos: primeiro nome """&TRIM(C18)&""" + loja "&F18&" + dia "&TEXT(DAY(B18),"00")&"/"&TEXT(MONTH(B18),"00")&"/"&YEAR(B18)&" (ver aba Varredura)","") -> Buscar em vendas e atendimentos: primeiro nome "João" + loja Eldorado + dia 16/09/2026 (ver aba Varredura) | K18: Cecília Fernandes | L18: 799.921.299-72 | M18: 4483 | N18: 45222 | O18: Provavelmente migrou com outro CPF: 934.365.449-90 | Q18: Atendente | R18: Resgates desde mar/25 | S18: Com erro | T18: % com erro | U18: Desconto a mais (R$)
H19: {=IF(NOT(ISNUMBER(A19)),"",IF(INDEX(Resgates!$B:$B,A19)<>"","CPF não está no cadastro",IF(ISNUMBER(SEARCH(" ",TRIM(C19))),IF(COUNTIF(Clientes!$A$2:$A$2396,TRIM(C19))>1,"Nome repetido no cadastro","Nome não encontrado no cadastro"),"Só o primeiro nome")))} | I19: {=IF(H19="","",IF(LEFT(INDEX(Resgates!$K:$K,A19),9)="Sugestão:",INDEX(Resgates!$K:$K,A19),IF(H19="Nome repetido no cadastro",_xlfn.TEXTJOIN(" / ",TRUE,_xlfn._xlws.FILTER(Clientes!$A$2:$A$2396&" – "&Clientes!$B$2:$B$2396&" (cadastro "&Clientes!$G$2:$G$2396&")",Clientes!$A$2:$A$2396=TRIM(C19))),IF(H19="Só o primeiro nome",COUNTIF(Clientes!$A$2:$A$2396,TRIM(C19)&" *")&" clientes com esse primeiro nome – confirmar com a loja/atendente",IF(H19="CPF não está no cadastro","Conferir se o CPF foi digitado errado ou se o cliente não foi cadastrado","Confirmar com a loja")))))} | J19: =IF(H19="Só o primeiro nome","Buscar em vendas e atendimentos: primeiro nome """&TRIM(C19)&""" + loja "&F19&" + dia "&TEXT(DAY(B19),"00")&"/"&TEXT(MONTH(B19),"00")&"/"&YEAR(B19)&" (ver aba Varredura)","") | K19: Renata Soares | L19: 731.675.299-89 | M19: 6167 | N19: 44944 | O19: Encerrado: pontos de 2023 já teriam vencido (regra de 12 meses) | Q19: {=_xlfn._xlws.SORT(_xlfn.UNIQUE(_xlfn._xlws.FILTER(Resgates!$I$2:$I$597,(Resgates!$A$2:$A$597>='Regras e Parâmetros'!$A$12)*(Resgates!$I$2:$I$597<>""))))} -> Ana Paula | R19: =IF(Q19="","",COUNTIFS(Resgates!$I$2:$I$597,Q19,Resgates!$A$2:$A$597,">="&'Regras e Parâmetros'!$A$12)) -> 8 | S19: =IF(Q19="","",COUNTIFS(Resgates!$I$2:$I$597,Q19,Resgates!$G$2:$G$597,">0")) -> 0 | T19: =IF(Q19="","",IF(R19=0,0,S19/R19)) -> 0 | U19: =IF(Q19="","",SUMIFS(Resgates!$G$2:$G$597,Resgates!$I$2:$I$597,Q19,Resgates!$G$2:$G$597,">0")) -> 0
H20: {=IF(NOT(ISNUMBER(A20)),"",IF(INDEX(Resgates!$B:$B,A20)<>"","CPF não está no cadastro",IF(ISNUMBER(SEARCH(" ",TRIM(C20))),IF(COUNTIF(Clientes!$A$2:$A$2396,TRIM(C20))>1,"Nome repetido no cadastro","Nome não encontrado no cadastro"),"Só o primeiro nome")))} | I20: {=IF(H20="","",IF(LEFT(INDEX(Resgates!$K:$K,A20),9)="Sugestão:",INDEX(Resgates!$K:$K,A20),IF(H20="Nome repetido no cadastro",_xlfn.TEXTJOIN(" / ",TRUE,_xlfn._xlws.FILTER(Clientes!$A$2:$A$2396&" – "&Clientes!$B$2:$B$2396&" (cadastro "&Clientes!$G$2:$G$2396&")",Clientes!$A$2:$A$2396=TRIM(C20))),IF(H20="Só o primeiro nome",COUNTIF(Clientes!$A$2:$A$2396,TRIM(C20)&" *")&" clientes com esse primeiro nome – confirmar com a loja/atendente",IF(H20="CPF não está no cadastro","Conferir se o CPF foi digitado errado ou se o cliente não foi cadastrado","Confirmar com a loja")))))} | J20: =IF(H20="Só o primeiro nome","Buscar em vendas e atendimentos: primeiro nome """&TRIM(C20)&""" + loja "&F20&" + dia "&TEXT(DAY(B20),"00")&"/"&TEXT(MONTH(B20),"00")&"/"&YEAR(B20)&" (ver aba Varredura)","") | K20: Camila Nogueira | L20: 890.646.714-19 | M20: 1793 | N20: 44945 | O20: Encerrado: pontos de 2023 já teriam vencido (regra de 12 meses) | Q20: Beatriz | R20: =IF(Q20="","",COUNTIFS(Resgates!$I$2:$I$597,Q20,Resgates!$A$2:$A$597,">="&'Regras e Parâmetros'!$A$12)) -> 5 | S20: =IF(Q20="","",COUNTIFS(Resgates!$I$2:$I$597,Q20,Resgates!$G$2:$G$597,">0")) -> 0 | T20: =IF(Q20="","",IF(R20=0,0,S20/R20)) -> 0 | U20: =IF(Q20="","",SUMIFS(Resgates!$G$2:$G$597,Resgates!$I$2:$I$597,Q20,Resgates!$G$2:$G$597,">0")) -> 0
H21: {=IF(NOT(ISNUMBER(A21)),"",IF(INDEX(Resgates!$B:$B,A21)<>"","CPF não está no cadastro",IF(ISNUMBER(SEARCH(" ",TRIM(C21))),IF(COUNTIF(Clientes!$A$2:$A$2396,TRIM(C21))>1,"Nome repetido no cadastro","Nome não encontrado no cadastro"),"Só o primeiro nome")))} | I21: {=IF(H21="","",IF(LEFT(INDEX(Resgates!$K:$K,A21),9)="Sugestão:",INDEX(Resgates!$K:$K,A21),IF(H21="Nome repetido no cadastro",_xlfn.TEXTJOIN(" / ",TRUE,_xlfn._xlws.FILTER(Clientes!$A$2:$A$2396&" – "&Clientes!$B$2:$B$2396&" (cadastro "&Clientes!$G$2:$G$2396&")",Clientes!$A$2:$A$2396=TRIM(C21))),IF(H21="Só o primeiro nome",COUNTIF(Clientes!$A$2:$A$2396,TRIM(C21)&" *")&" clientes com esse primeiro nome – confirmar com a loja/atendente",IF(H21="CPF não está no cadastro","Conferir se o CPF foi digitado errado ou se o cliente não foi cadastrado","Confirmar com a loja")))))} | J21: =IF(H21="Só o primeiro nome","Buscar em vendas e atendimentos: primeiro nome """&TRIM(C21)&""" + loja "&F21&" + dia "&TEXT(DAY(B21),"00")&"/"&TEXT(MONTH(B21),"00")&"/"&YEAR(B21)&" (ver aba Varredura)","") | K21: Rebeca Fernandes Moura | L21: 610.429.147-37 | M21: 3600 | N21: 45187 | O21: Encerrado: pontos de 2023 já teriam vencido (regra de 12 meses) | Q21: Bia | R21: =IF(Q21="","",COUNTIFS(Resgates!$I$2:$I$597,Q21,Resgates!$A$2:$A$597,">="&'Regras e Parâmetros'!$A$12)) -> 10 | S21: =IF(Q21="","",COUNTIFS(Resgates!$I$2:$I$597,Q21,Resgates!$G$2:$G$597,">0")) -> 0 | T21: =IF(Q21="","",IF(R21=0,0,S21/R21)) -> 0 | U21: =IF(Q21="","",SUMIFS(Resgates!$G$2:$G$597,Resgates!$I$2:$I$597,Q21,Resgates!$G$2:$G$597,">0")) -> 0
H22: {=IF(NOT(ISNUMBER(A22)),"",IF(INDEX(Resgates!$B:$B,A22)<>"","CPF não está no cadastro",IF(ISNUMBER(SEARCH(" ",TRIM(C22))),IF(COUNTIF(Clientes!$A$2:$A$2396,TRIM(C22))>1,"Nome repetido no cadastro","Nome não encontrado no cadastro"),"Só o primeiro nome")))} | I22: {=IF(H22="","",IF(LEFT(INDEX(Resgates!$K:$K,A22),9)="Sugestão:",INDEX(Resgates!$K:$K,A22),IF(H22="Nome repetido no cadastro",_xlfn.TEXTJOIN(" / ",TRUE,_xlfn._xlws.FILTER(Clientes!$A$2:$A$2396&" – "&Clientes!$B$2:$B$2396&" (cadastro "&Clientes!$G$2:$G$2396&")",Clientes!$A$2:$A$2396=TRIM(C22))),IF(H22="Só o primeiro nome",COUNTIF(Clientes!$A$2:$A$2396,TRIM(C22)&" *")&" clientes com esse primeiro nome – confirmar com a loja/atendente",IF(H22="CPF não está no cadastro","Conferir se o CPF foi digitado errado ou se o cliente não foi cadastrado","Confirmar com a loja")))))} | J22: =IF(H22="Só o primeiro nome","Buscar em vendas e atendimentos: primeiro nome """&TRIM(C22)&""" + loja "&F22&" + dia "&TEXT(DAY(B22),"00")&"/"&TEXT(MONTH(B22),"00")&"/"&YEAR(B22)&" (ver aba Varredura)","") | K22: Priscila Barbosa | L22: 349.803.647-56 | M22: 2705 | N22: 45112 | O22: Encerrado: pontos de 2023 já teriam vencido (regra de 12 meses) | Q22: Bianca | R22: =IF(Q22="","",COUNTIFS(Resgates!$I$2:$I$597,Q22,Resgates!$A$2:$A$597,">="&'Regras e Parâmetros'!$A$12)) -> 2 | S22: =IF(Q22="","",COUNTIFS(Resgates!$I$2:$I$597,Q22,Resgates!$G$2:$G$597,">0")) -> 0 | T22: =IF(Q22="","",IF(R22=0,0,S22/R22)) -> 0 | U22: =IF(Q22="","",SUMIFS(Resgates!$G$2:$G$597,Resgates!$I$2:$I$597,Q22,Resgates!$G$2:$G$597,">0")) -> 0
H23: {=IF(NOT(ISNUMBER(A23)),"",IF(INDEX(Resgates!$B:$B,A23)<>"","CPF não está no cadastro",IF(ISNUMBER(SEARCH(" ",TRIM(C23))),IF(COUNTIF(Clientes!$A$2:$A$2396,TRIM(C23))>1,"Nome repetido no cadastro","Nome não encontrado no cadastro"),"Só o primeiro nome")))} | I23: {=IF(H23="","",IF(LEFT(INDEX(Resgates!$K:$K,A23),9)="Sugestão:",INDEX(Resgates!$K:$K,A23),IF(H23="Nome repetido no cadastro",_xlfn.TEXTJOIN(" / ",TRUE,_xlfn._xlws.FILTER(Clientes!$A$2:$A$2396&" – "&Clientes!$B$2:$B$2396&" (cadastro "&Clientes!$G$2:$G$2396&")",Clientes!$A$2:$A$2396=TRIM(C23))),IF(H23="Só o primeiro nome",COUNTIF(Clientes!$A$2:$A$2396,TRIM(C23)&" *")&" clientes com esse primeiro nome – confirmar com a loja/atendente",IF(H23="CPF não está no cadastro","Conferir se o CPF foi digitado errado ou se o cliente não foi cadastrado","Confirmar com a loja")))))} | J23: =IF(H23="Só o primeiro nome","Buscar em vendas e atendimentos: primeiro nome """&TRIM(C23)&""" + loja "&F23&" + dia "&TEXT(DAY(B23),"00")&"/"&TEXT(MONTH(B23),"00")&"/"&YEAR(B23)&" (ver aba Varredura)","") | K23: Vitória Mendes | L23: 921.341.835-35 | M23: 3930 | N23: 45042 | O23: Encerrado: pontos de 2023 já teriam vencido (regra de 12 meses) | Q23: Camila | R23: =IF(Q23="","",COUNTIFS(Resgates!$I$2:$I$597,Q23,Resgates!$A$2:$A$597,">="&'Regras e Parâmetros'!$A$12)) -> 5 | S23: =IF(Q23="","",COUNTIFS(Resgates!$I$2:$I$597,Q23,Resgates!$G$2:$G$597,">0")) -> 0 | T23: =IF(Q23="","",IF(R23=0,0,S23/R23)) -> 0 | U23: =IF(Q23="","",SUMIFS(Resgates!$G$2:$G$597,Resgates!$I$2:$I$597,Q23,Resgates!$G$2:$G$597,">0")) -> 0
