Workbook

Sheet PINHEIROS
A1: SKU | B1: CÓDIGO CD | C1: QTD | D1: STATUS CATÁLOGO | E1: OBS | F1: AVARIA (real) | H1: RESUMO AVARIA – PINHEIROS
A2: VLT-MOL-002-OLI-GG | B2: =_xlfn.XLOOKUP(A2,CATÁLOGO!$A$2:$A$846,CATÁLOGO!$B$2:$B$846,"FORA DO CATÁLOGO") -> MOL002VGG | C2: 0 | D2: =_xlfn.XLOOKUP(A2,CATÁLOGO!$A$2:$A$846,CATÁLOGO!$E$2:$E$846,"FORA DO CATÁLOGO") -> Fora do catálogo 2026 | F2: =SUMIFS('AVARIA PINHEIROS'!$C$2:$C$24,'AVARIA PINHEIROS'!$A$2:$A$24,A2) -> 0 | H2: Tipo de avaria | I2: Real (contada)
A3: VLT-CAL-001-VIN-G | B3: =_xlfn.XLOOKUP(A3,CATÁLOGO!$A$2:$A$846,CATÁLOGO!$B$2:$B$846,"FORA DO CATÁLOGO") -> CAL001H42 | C3: 1 | D3: =_xlfn.XLOOKUP(A3,CATÁLOGO!$A$2:$A$846,CATÁLOGO!$E$2:$E$846,"FORA DO CATÁLOGO") -> Fora do catálogo 2026 | F3: =SUMIFS('AVARIA PINHEIROS'!$C$2:$C$24,'AVARIA PINHEIROS'!$A$2:$A$24,A3) -> 0 | H3: Estoque contado (inclui avaria) | I3: =SUM(C2:C725)+I4 -> 2438
A4: VLT-ACE-001-PRE-U | B4: =_xlfn.XLOOKUP(A4,CATÁLOGO!$A$2:$A$846,CATÁLOGO!$B$2:$B$846,"FORA DO CATÁLOGO") -> ACE001PU | C4: 0 | D4: =_xlfn.XLOOKUP(A4,CATÁLOGO!$A$2:$A$846,CATÁLOGO!$E$2:$E$846,"FORA DO CATÁLOGO") -> Fora do catálogo 2026 | E4: avaria? | 1 peça(s) transferida(s) p/ aba AVARIA PINHEIROS (decisão 15/10) | F4: =SUMIFS('AVARIA PINHEIROS'!$C$2:$C$24,'AVARIA PINHEIROS'!$A$2:$A$24,A4) -> 1 | H4: Peças com avaria | I4: =SUM(F2:F725) -> 80
A5: VLT-TRI-003-BEG-M | B5: =_xlfn.XLOOKUP(A5,CATÁLOGO!$A$2:$A$846,CATÁLOGO!$B$2:$B$846,"FORA DO CATÁLOGO") -> TRI003GM | C5: 1 | D5: =_xlfn.XLOOKUP(A5,CATÁLOGO!$A$2:$A$846,CATÁLOGO!$E$2:$E$846,"FORA DO CATÁLOGO") -> Fora do catálogo 2026 | F5: =SUMIFS('AVARIA PINHEIROS'!$C$2:$C$24,'AVARIA PINHEIROS'!$A$2:$A$24,A5) -> 0 | H5: Estoque vendável | I5: =I3-I4 -> 2358
A6: VLT-TRI-003-BEG-GG | B6: =_xlfn.XLOOKUP(A6,CATÁLOGO!$A$2:$A$846,CATÁLOGO!$B$2:$B$846,"FORA DO CATÁLOGO") -> TRI003GGG | C6: 1 | D6: =_xlfn.XLOOKUP(A6,CATÁLOGO!$A$2:$A$846,CATÁLOGO!$E$2:$E$846,"FORA DO CATÁLOGO") -> Fora do catálogo 2026 | F6: =SUMIFS('AVARIA PINHEIROS'!$C$2:$C$24,'AVARIA PINHEIROS'!$A$2:$A$24,A6) -> 0 | H6: % avaria | I6: =I4/I3 -> 0.032813782
A7: VLT-TRI-003-MRR-P | B7: =_xlfn.XLOOKUP(A7,CATÁLOGO!$A$2:$A$846,CATÁLOGO!$B$2:$B$846,"FORA DO CATÁLOGO") -> TRI003MP | C7: 1 | D7: =_xlfn.XLOOKUP(A7,CATÁLOGO!$A$2:$A$846,CATÁLOGO!$E$2:$E$846,"FORA DO CATÁLOGO") -> Fora do catálogo 2026 | F7: =SUMIFS('AVARIA PINHEIROS'!$C$2:$C$24,'AVARIA PINHEIROS'!$A$2:$A$24,A7) -> 0 | H7: SKUs afetados | I7: =COUNTIF(F2:F725,">0") -> 23
A8: VLT-TRI-003-MRR-M | B8: =_xlfn.XLOOKUP(A8,CATÁLOGO!$A$2:$A$846,CATÁLOGO!$B$2:$B$846,"FORA DO CATÁLOGO") -> TRI003MM | C8: 1 | D8: =_xlfn.XLOOKUP(A8,CATÁLOGO!$A$2:$A$846,CATÁLOGO!$E$2:$E$846,"FORA DO CATÁLOGO") -> Fora do catálogo 2026 | F8: =SUMIFS('AVARIA PINHEIROS'!$C$2:$C$24,'AVARIA PINHEIROS'!$A$2:$A$24,A8) -> 0 | H8: % avaria – média das 4 lojas | I8: ='AVARIA ESTIMADA'!F14 -> 0.029957854
A9: VLT-TRI-003-MRR-G | B9: =_xlfn.XLOOKUP(A9,CATÁLOGO!$A$2:$A$846,CATÁLOGO!$B$2:$B$846,"FORA DO CATÁLOGO") -> TRI003MG | C9: 1 | D9: =_xlfn.XLOOKUP(A9,CATÁLOGO!$A$2:$A$846,CATÁLOGO!$E$2:$E$846,"FORA DO CATÁLOGO") -> Fora do catálogo 2026 | F9: =SUMIFS('AVARIA PINHEIROS'!$C$2:$C$24,'AVARIA PINHEIROS'!$A$2:$A$24,A9) -> 0
A10: VLT-BER-001-BRA-P | B10: =_xlfn.XLOOKUP(A10,CATÁLOGO!$A$2:$A$846,CATÁLOGO!$B$2:$B$846,"FORA DO CATÁLOGO") -> BER001B38 | C10: 6 | D10: =_xlfn.XLOOKUP(A10,CATÁLOGO!$A$2:$A$846,CATÁLOGO!$E$2:$E$846,"FORA DO CATÁLOGO") -> Ativo | F10: =SUMIFS('AVARIA PINHEIROS'!$C$2:$C$24,'AVARIA PINHEIROS'!$A$2:$A$24,A10) -> 0 | H10: SKUs com avaria (maior → menor)
A11: VLT-BER-001-BRA-M | B11: =_xlfn.XLOOKUP(A11,CATÁLOGO!$A$2:$A$846,CATÁLOGO!$B$2:$B$846,"FORA DO CATÁLOGO") -> BER001B40 | C11: 6 | D11: =_xlfn.XLOOKUP(A11,CATÁLOGO!$A$2:$A$846,CATÁLOGO!$E$2:$E$846,"FORA DO CATÁLOGO") -> Ativo | F11: =SUMIFS('AVARIA PINHEIROS'!$C$2:$C$24,'AVARIA PINHEIROS'!$A$2:$A$24,A11) -> 0 | H11: SKU | I11: PEÇAS
A12: VLT-BER-001-BRA-G | B12: =_xlfn.XLOOKUP(A12,CATÁLOGO!$A$2:$A$846,CATÁLOGO!$B$2:$B$846,"FORA DO CATÁLOGO") -> BER001B42 | C12: 6 | D12: =_xlfn.XLOOKUP(A12,CATÁLOGO!$A$2:$A$846,CATÁLOGO!$E$2:$E$846,"FORA DO CATÁLOGO") -> Ativo | F12: =SUMIFS('AVARIA PINHEIROS'!$C$2:$C$24,'AVARIA PINHEIROS'!$A$2:$A$24,A12) -> 0 | H12: {=_xlfn._xlws.SORT(_xlfn._xlws.FILTER(_xlfn.HSTACK(A2:A725,F2:F725),F2:F725>0,"sem avaria"),2,-1)} -> VLT-CAL-023-LIL-M | I12: 7
A13: VLT-BER-001-BRA-GG | B13: =_xlfn.XLOOKUP(A13,CATÁLOGO!$A$2:$A$846,CATÁLOGO!$B$2:$B$846,"FORA DO CATÁLOGO") -> BER001B44 | C13: 4 | D13: =_xlfn.XLOOKUP(A13,CATÁLOGO!$A$2:$A$846,CATÁLOGO!$E$2:$E$846,"FORA DO CATÁLOGO") -> Ativo | F13: =SUMIFS('AVARIA PINHEIROS'!$C$2:$C$24,'AVARIA PINHEIROS'!$A$2:$A$24,A13) -> 0 | H13: VLT-CAL-003-PRE-G | I13: 6
A14: VLT-CAL-003-PRE-P | B14: =_xlfn.XLOOKUP(A14,CATÁLOGO!$A$2:$A$846,CATÁLOGO!$B$2:$B$846,"FORA DO CATÁLOGO") -> CAL003P38 | C14: 6 | D14: =_xlfn.XLOOKUP(A14,CATÁLOGO!$A$2:$A$846,CATÁLOGO!$E$2:$E$846,"FORA DO CATÁLOGO") -> Ativo | F14: =SUMIFS('AVARIA PINHEIROS'!$C$2:$C$24,'AVARIA PINHEIROS'!$A$2:$A$24,A14) -> 0 | H14: VLT-TOP-006-MRR-G | I14: 5
A15: VLT-CAL-003-PRE-M | B15: =_xlfn.XLOOKUP(A15,CATÁLOGO!$A$2:$A$846,CATÁLOGO!$B$2:$B$846,"FORA DO CATÁLOGO") -> CAL003P40 | C15: 6 | D15: =_xlfn.XLOOKUP(A15,CATÁLOGO!$A$2:$A$846,CATÁLOGO!$E$2:$E$846,"FORA DO CATÁLOGO") -> Ativo | F15: =SUMIFS('AVARIA PINHEIROS'!$C$2:$C$24,'AVARIA PINHEIROS'!$A$2:$A$24,A15) -> 0 | H15: VLT-CAL-011-LIL-P | I15: 5
A16: VLT-CAL-003-PRE-G | B16: =_xlfn.XLOOKUP(A16,CATÁLOGO!$A$2:$A$846,CATÁLOGO!$B$2:$B$846,"FORA DO CATÁLOGO") -> CAL003P42 | C16: 0 | D16: =_xlfn.XLOOKUP(A16,CATÁLOGO!$A$2:$A$846,CATÁLOGO!$E$2:$E$846,"FORA DO CATÁLOGO") -> Ativo | E16: avaria? | 6 peça(s) transferida(s) p/ aba AVARIA PINHEIROS (decisão 15/10) | F16: =SUMIFS('AVARIA PINHEIROS'!$C$2:$C$24,'AVARIA PINHEIROS'!$A$2:$A$24,A16) -> 6 | H16: VLT-CAL-024-AZM-P | I16: 5
A17: VLT-CAL-003-PRE-GG | B17: =_xlfn.XLOOKUP(A17,CATÁLOGO!$A$2:$A$846,CATÁLOGO!$B$2:$B$846,"FORA DO CATÁLOGO") -> CAL003P44 | C17: 4 | D17: =_xlfn.XLOOKUP(A17,CATÁLOGO!$A$2:$A$846,CATÁLOGO!$E$2:$E$846,"FORA DO CATÁLOGO") -> Ativo | E17: provador | SKU corrigido (era VLT-CLA-003-PRE-44) | F17: =SUMIFS('AVARIA PINHEIROS'!$C$2:$C$24,'AVARIA PINHEIROS'!$A$2:$A$24,A17) -> 0 | H17: VLT-TOP-001-AMA-G | I17: 5
A18: VLT-CAL-004-CIN-XP | B18: =_xlfn.XLOOKUP(A18,CATÁLOGO!$A$2:$A$846,CATÁLOGO!$B$2:$B$846,"FORA DO CATÁLOGO") -> CAL004C36 | C18: 1 | D18: =_xlfn.XLOOKUP(A18,CATÁLOGO!$A$2:$A$846,CATÁLOGO!$E$2:$E$846,"FORA DO CATÁLOGO") -> Ativo | F18: =SUMIFS('AVARIA PINHEIROS'!$C$2:$C$24,'AVARIA PINHEIROS'!$A$2:$A$24,A18) -> 0 | H18: VLT-CAM-020-AMA-G | I18: 5
A19: VLT-CAL-004-CIN-P | B19: =_xlfn.XLOOKUP(A19,CATÁLOGO!$A$2:$A$846,CATÁLOGO!$B$2:$B$846,"FORA DO CATÁLOGO") -> CAL004C38 | C19: 2 | D19: =_xlfn.XLOOKUP(A19,CATÁLOGO!$A$2:$A$846,CATÁLOGO!$E$2:$E$846,"FORA DO CATÁLOGO") -> Ativo | F19: =SUMIFS('AVARIA PINHEIROS'!$C$2:$C$24,'AVARIA PINHEIROS'!$A$2:$A$24,A19) -> 0 | H19: VLT-VES-006-MRR-G | I19: 4
A20: VLT-CAL-004-CIN-M | B20: =_xlfn.XLOOKUP(A20,CATÁLOGO!$A$2:$A$846,CATÁLOGO!$B$2:$B$846,"FORA DO CATÁLOGO") -> CAL004C40 | C20: 2 | D20: =_xlfn.XLOOKUP(A20,CATÁLOGO!$A$2:$A$846,CATÁLOGO!$E$2:$E$846,"FORA DO CATÁLOGO") -> Ativo | F20: =SUMIFS('AVARIA PINHEIROS'!$C$2:$C$24,'AVARIA PINHEIROS'!$A$2:$A$24,A20) -> 0 | H20: VLT-CAL-016-OLI-P | I20: 4
A21: VLT-CAL-004-CIN-G | B21: =_xlfn.XLOOKUP(A21,CATÁLOGO!$A$2:$A$846,CATÁLOGO!$B$2:$B$846,"FORA DO CATÁLOGO") -> CAL004C42 | C21: 2 | D21: =_xlfn.XLOOKUP(A21,CATÁLOGO!$A$2:$A$846,CATÁLOGO!$E$2:$E$846,"FORA DO CATÁLOGO") -> Ativo | F21: =SUMIFS('AVARIA PINHEIROS'!$C$2:$C$24,'AVARIA PINHEIROS'!$A$2:$A$24,A21) -> 0 | H21: VLT-CAL-016-OLI-M | I21: 4
A22: VLT-CAL-004-CIN-GG | B22: =_xlfn.XLOOKUP(A22,CATÁLOGO!$A$2:$A$846,CATÁLOGO!$B$2:$B$846,"FORA DO CATÁLOGO") -> CAL004C44 | C22: 1 | D22: =_xlfn.XLOOKUP(A22,CATÁLOGO!$A$2:$A$846,CATÁLOGO!$E$2:$E$846,"FORA DO CATÁLOGO") -> Ativo | F22: =SUMIFS('AVARIA PINHEIROS'!$C$2:$C$24,'AVARIA PINHEIROS'!$A$2:$A$24,A22) -> 0 | H22: VLT-BER-007-AZM-G | I22: 4
A23: VLT-CAL-004-CIN-XG | B23: =_xlfn.XLOOKUP(A23,CATÁLOGO!$A$2:$A$846,CATÁLOGO!$B$2:$B$846,"FORA DO CATÁLOGO") -> CAL004C46 | C23: 1 | D23: =_xlfn.XLOOKUP(A23,CATÁLOGO!$A$2:$A$846,CATÁLOGO!$E$2:$E$846,"FORA DO CATÁLOGO") -> Ativo | F23: =SUMIFS('AVARIA PINHEIROS'!$C$2:$C$24,'AVARIA PINHEIROS'!$A$2:$A$24,A23) -> 0 | H23: VLT-CAM-017-AMA-G | I23: 4
A24: VLT-CAL-004-BEG-XP | B24: =_xlfn.XLOOKUP(A24,CATÁLOGO!$A$2:$A$846,CATÁLOGO!$B$2:$B$846,"FORA DO CATÁLOGO") -> CAL004G36 | C24: 1 | D24: =_xlfn.XLOOKUP(A24,CATÁLOGO!$A$2:$A$846,CATÁLOGO!$E$2:$E$846,"FORA DO CATÁLOGO") -> Ativo | F24: =SUMIFS('AVARIA PINHEIROS'!$C$2:$C$24,'AVARIA PINHEIROS'!$A$2:$A$24,A24) -> 0 | H24: VLT-CAM-020-AMA-P | I24: 4
A25: VLT-CAL-004-BEG-M | B25: =_xlfn.XLOOKUP(A25,CATÁLOGO!$A$2:$A$846,CATÁLOGO!$B$2:$B$846,"FORA DO CATÁLOGO") -> CAL004G40 | C25: 1 | D25: =_xlfn.XLOOKUP(A25,CATÁLOGO!$A$2:$A$846,CATÁLOGO!$E$2:$E$846,"FORA DO CATÁLOGO") -> Ativo | F25: =SUMIFS('AVARIA PINHEIROS'!$C$2:$C$24,'AVARIA PINHEIROS'!$A$2:$A$24,A25) -> 0 | H25: VLT-VES-007-OLI-GG | I25: 3
A26: VLT-CAL-004-BEG-G | B26: =_xlfn.XLOOKUP(A26,CATÁLOGO!$A$2:$A$846,CATÁLOGO!$B$2:$B$846,"FORA DO CATÁLOGO") -> CAL004G42 | C26: 1 | D26: =_xlfn.XLOOKUP(A26,CATÁLOGO!$A$2:$A$846,CATÁLOGO!$E$2:$E$846,"FORA DO CATÁLOGO") -> Ativo | F26: =SUMIFS('AVARIA PINHEIROS'!$C$2:$C$24,'AVARIA PINHEIROS'!$A$2:$A$24,A26) -> 0 | H26: VLT-VES-009-BEG-G | I26: 3
A27: VLT-CAL-004-BEG-GG | B27: =_xlfn.XLOOKUP(A27,CATÁLOGO!$A$2:$A$846,CATÁLOGO!$B$2:$B$846,"FORA DO CATÁLOGO") -> CAL004G44 | C27: 0 | D27: =_xlfn.XLOOKUP(A27,CATÁLOGO!$A$2:$A$846,CATÁLOGO!$E$2:$E$846,"FORA DO CATÁLOGO") -> Ativo | F27: =SUMIFS('AVARIA PINHEIROS'!$C$2:$C$24,'AVARIA PINHEIROS'!$A$2:$A$24,A27) -> 0 | H27: VLT-CAM-004-PRE-M | I27: 2
A28: VLT-CAL-005-PRE-XP | B28: =_xlfn.XLOOKUP(A28,CATÁLOGO!$A$2:$A$846,CATÁLOGO!$B$2:$B$846,"FORA DO CATÁLOGO") -> CAL005P36 | C28: 4 | D28: =_xlfn.XLOOKUP(A28,CATÁLOGO!$A$2:$A$846,CATÁLOGO!$E$2:$E$846,"FORA DO CATÁLOGO") -> Ativo | F28: =SUMIFS('AVARIA PINHEIROS'!$C$2:$C$24,'AVARIA PINHEIROS'!$A$2:$A$24,A28) -> 0 | H28: VLT-BER-006-LIL-G | I28: 2
A29: VLT-CAL-005-PRE-P | B29: =_xlfn.XLOOKUP(A29,CATÁLOGO!$A$2:$A$846,CATÁLOGO!$B$2:$B$846,"FORA DO CATÁLOGO") -> CAL005P38 | C29: 6 | D29: =_xlfn.XLOOKUP(A29,CATÁLOGO!$A$2:$A$846,CATÁLOGO!$E$2:$E$846,"FORA DO CATÁLOGO") -> Ativo | F29: =SUMIFS('AVARIA PINHEIROS'!$C$2:$C$24,'AVARIA PINHEIROS'!$A$2:$A$24,A29) -> 0 | H29: VLT-SAI-009-BRA-P | I29: 2
... A31: VLT-CAL-005-PRE-G | B31: =_xlfn.XLOOKUP(A31,CATÁLOGO!$A$2:$A$846,CATÁLOGO!$B$2:$B$846,"FORA DO CATÁLOGO") -> CAL005P42 | C31: 5 | D31: =_xlfn.XLOOKUP(A31,CATÁLOGO!$A$2:$A$846,CATÁLOGO!$E$2:$E$846,"FORA DO CATÁLOGO") -> Ativo | F31: =SUMIFS('AVARIA PINHEIROS'!$C$2:$C$24,'AVARIA PINHEIROS'!$A$2:$A$24,A31) -> 0 | H31: VLT-ACE-001-PRE-U | I31: 1
A32: VLT-CAL-005-PRE-GG | B32: =_xlfn.XLOOKUP(A32,CATÁLOGO!$A$2:$A$846,CATÁLOGO!$B$2:$B$846,"FORA DO CATÁLOGO") -> CAL005P44 | C32: 4 | D32: =_xlfn.XLOOKUP(A32,CATÁLOGO!$A$2:$A$846,CATÁLOGO!$E$2:$E$846,"FORA DO CATÁLOGO") -> Ativo | E32: provador | F32: =SUMIFS('AVARIA PINHEIROS'!$C$2:$C$24,'AVARIA PINHEIROS'!$A$2:$A$24,A32) -> 0 | H32: VLT-MOL-008-VIN-G | I32: 1
A33: VLT-TOP-002-AZM-P | B33: =_xlfn.XLOOKUP(A33,CATÁLOGO!$A$2:$A$846,CATÁLOGO!$B$2:$B$846,"FORA DO CATÁLOGO") -> TOP002AP | C33: 3 | D33: =_xlfn.XLOOKUP(A33,CATÁLOGO!$A$2:$A$846,CATÁLOGO!$E$2:$E$846,"FORA DO CATÁLOGO") -> Ativo | F33: =SUMIFS('AVARIA PINHEIROS'!$C$2:$C$24,'AVARIA PINHEIROS'!$A$2:$A$24,A33) -> 0 | H33: VLT-MOL-008-VIN-GG | I33: 1
A34: VLT-TOP-002-AZM-M | B34: =_xlfn.XLOOKUP(A34,CATÁLOGO!$A$2:$A$846,CATÁLOGO!$B$2:$B$846,"FORA DO CATÁLOGO") -> TOP002AM | C34: 6 | D34: =_xlfn.XLOOKUP(A34,CATÁLOGO!$A$2:$A$846,CATÁLOGO!$E$2:$E$846,"FORA DO CATÁLOGO") -> Ativo | F34: =SUMIFS('AVARIA PINHEIROS'!$C$2:$C$24,'AVARIA PINHEIROS'!$A$2:$A$24,A34) -> 0 | H34: VLT-TOP-010-AMA-M | I34: 1
A35: VLT-TOP-002-AZM-G | B35: =_xlfn.XLOOKUP(A35,CATÁLOGO!$A$2:$A$846,CATÁLOGO!$B$2:$B$846,"FORA DO CATÁLOGO") -> TOP002AG | C35: 5 | D35: =_xlfn.XLOOKUP(A35,CATÁLOGO!$A$2:$A$846,CATÁLOGO!$E$2:$E$846,"FORA DO CATÁLOGO") -> Ativo | F35: =SUMIFS('AVARIA PINHEIROS'!$C$2:$C$24,'AVARIA PINHEIROS'!$A$2:$A$24,A35) -> 0
A36: VLT-TOP-002-AZM-GG | B36: =_xlfn.XLOOKUP(A36,CATÁLOGO!$A$2:$A$846,CATÁLOGO!$B$2:$B$846,"FORA DO CATÁLOGO") -> TOP002AGG | C36: 2 | D36: =_xlfn.XLOOKUP(A36,CATÁLOGO!$A$2:$A$846,CATÁLOGO!$E$2:$E$846,"FORA DO CATÁLOGO") -> Ativo | F36: =SUMIFS('AVARIA PINHEIROS'!$C$2:$C$24,'AVARIA PINHEIROS'!$A$2:$A$24,A36) -> 0
A37: VLT-TOP-002-PRE-P | B37: =_xlfn.XLOOKUP(A37,CATÁLOGO!$A$2:$A$846,CATÁLOGO!$B$2:$B$846,"FORA DO CATÁLOGO") -> TOP002PP | C37: 2 | D37: =_xlfn.XLOOKUP(A37,CATÁLOGO!$A$2:$A$846,CATÁLOGO!$E$2:$E$846,"FORA DO CATÁLOGO") -> Descontinuado | F37: =SUMIFS('AVARIA PINHEIROS'!$C$2:$C$24,'AVARIA PINHEIROS'!$A$2:$A$24,A37) -> 0
A38: VLT-TOP-002-PRE-G | B38: =_xlfn.XLOOKUP(A38,CATÁLOGO!$A$2:$A$846,CATÁLOGO!$B$2:$B$846,"FORA DO CATÁLOGO") -> TOP002PG | C38: 1 | D38: =_xlfn.XLOOKUP(A38,CATÁLOGO!$A$2:$A$846,CATÁLOGO!$E$2:$E$846,"FORA DO CATÁLOGO") -> Descontinuado | E38: vitrine | F38: =SUMIFS('AVARIA PINHEIROS'!$C$2:$C$24,'AVARIA PINHEIROS'!$A$2:$A$24,A38) -> 0
A39: VLT-BER-002-CIN-XP | B39: =_xlfn.XLOOKUP(A39,CATÁLOGO!$A$2:$A$846,CATÁLOGO!$B$2:$B$846,"FORA DO CATÁLOGO") -> BER002C36 | C39: 1 | D39: =_xlfn.XLOOKUP(A39,CATÁLOGO!$A$2:$A$846,CATÁLOGO!$E$2:$E$846,"FORA DO CATÁLOGO") -> Ativo | F39: =SUMIFS('AVARIA PINHEIROS'!$C$2:$C$24,'AVARIA PINHEIROS'!$A$2:$A$24,A39) -> 0
A40: VLT-BER-002-CIN-P | B40: =_xlfn.XLOOKUP(A40,CATÁLOGO!$A$2:$A$846,CATÁLOGO!$B$2:$B$846,"FORA DO CATÁLOGO") -> BER002C38 | C40: 2 | D40: =_xlfn.XLOOKUP(A40,CATÁLOGO!$A$2:$A$846,CATÁLOGO!$E$2:$E$846,"FORA DO CATÁLOGO") -> Ativo | E40: vitrine | F40: =SUMIFS('AVARIA PINHEIROS'!$C$2:$C$24,'AVARIA PINHEIROS'!$A$2:$A$24,A40) -> 0
A41: VLT-BER-002-CIN-M | B41: =_xlfn.XLOOKUP(A41,CATÁLOGO!$A$2:$A$846,CATÁLOGO!$B$2:$B$846,"FORA DO CATÁLOGO") -> BER002C40 | C41: 3 | D41: =_xlfn.XLOOKUP(A41,CATÁLOGO!$A$2:$A$846,CATÁLOGO!$E$2:$E$846,"FORA DO CATÁLOGO") -> Ativo | F41: =SUMIFS('AVARIA PINHEIROS'!$C$2:$C$24,'AVARIA PINHEIROS'!$A$2:$A$24,A41) -> 0
...

Sheet ELDORADO
A1: SKU | B1: CÓDIGO CD | C1: QTD | D1: STATUS CATÁLOGO | E1: OBS | F1: AVARIA EST. | H1: RESUMO AVARIA – ELDORADO
A2: VLT-MOL-002-OLI-P | B2: =_xlfn.XLOOKUP(A2,CATÁLOGO!$A$2:$A$846,CATÁLOGO!$B$2:$B$846,"FORA DO CATÁLOGO") -> MOL002VP | C2: 1 | D2: =_xlfn.XLOOKUP(A2,CATÁLOGO!$A$2:$A$846,CATÁLOGO!$E$2:$E$846,"FORA DO CATÁLOGO") -> Fora do catálogo 2026 | E2: conferente: Jéssica | SKU só na Eldorado – existe na lista 2024 (fora do catálogo 2026), mantido | F2: =SUMIFS('AVARIA ESTIMADA'!$F$18:$F$40,'AVARIA ESTIMADA'!$A$18:$A$40,A2) -> 0 | H2: Tipo de avaria | I2: Estimada (decisão 13)
A3: VLT-CAL-001-OLI-XP | B3: =_xlfn.XLOOKUP(A3,CATÁLOGO!$A$2:$A$846,CATÁLOGO!$B$2:$B$846,"FORA DO CATÁLOGO") -> CAL001V36 | C3: 1 | D3: =_xlfn.XLOOKUP(A3,CATÁLOGO!$A$2:$A$846,CATÁLOGO!$E$2:$E$846,"FORA DO CATÁLOGO") -> Fora do catálogo 2026 | E3: conferente: Lari | SKU só na Eldorado – existe na lista 2024 (fora do catálogo 2026), mantido | F3: =SUMIFS('AVARIA ESTIMADA'!$F$18:$F$40,'AVARIA ESTIMADA'!$A$18:$A$40,A3) -> 0 | H3: Estoque contado (inclui avaria) | I3: =SUM(C2:C731) -> 2323
A4: VLT-CAL-001-OLI-P | B4: =_xlfn.XLOOKUP(A4,CATÁLOGO!$A$2:$A$846,CATÁLOGO!$B$2:$B$846,"FORA DO CATÁLOGO") -> CAL001V38 | C4: 1 | D4: =_xlfn.XLOOKUP(A4,CATÁLOGO!$A$2:$A$846,CATÁLOGO!$E$2:$E$846,"FORA DO CATÁLOGO") -> Fora do catálogo 2026 | E4: conferente: Thiago | F4: =SUMIFS('AVARIA ESTIMADA'!$F$18:$F$40,'AVARIA ESTIMADA'!$A$18:$A$40,A4) -> 0 | H4: Peças com avaria | I4: =SUM(F2:F731) -> 69
A5: VLT-CAL-001-OLI-G | B5: =_xlfn.XLOOKUP(A5,CATÁLOGO!$A$2:$A$846,CATÁLOGO!$B$2:$B$846,"FORA DO CATÁLOGO") -> CAL001V42 | C5: 1 | D5: =_xlfn.XLOOKUP(A5,CATÁLOGO!$A$2:$A$846,CATÁLOGO!$E$2:$E$846,"FORA DO CATÁLOGO") -> Fora do catálogo 2026 | E5: conferente: Lari | SKU só na Eldorado – existe na lista 2024 (fora do catálogo 2026), mantido | F5: =SUMIFS('AVARIA ESTIMADA'!$F$18:$F$40,'AVARIA ESTIMADA'!$A$18:$A$40,A5) -> 0 | H5: Estoque vendável | I5: =I3-I4 -> 2254
A6: VLT-CAL-001-OLI-GG | B6: =_xlfn.XLOOKUP(A6,CATÁLOGO!$A$2:$A$846,CATÁLOGO!$B$2:$B$846,"FORA DO CATÁLOGO") -> CAL001V44 | C6: 1 | D6: =_xlfn.XLOOKUP(A6,CATÁLOGO!$A$2:$A$846,CATÁLOGO!$E$2:$E$846,"FORA DO CATÁLOGO") -> Fora do catálogo 2026 | E6: conferente: Jéssica | SKU só na Eldorado – existe na lista 2024 (fora do catálogo 2026), mantido | F6: =SUMIFS('AVARIA ESTIMADA'!$F$18:$F$40,'AVARIA ESTIMADA'!$A$18:$A$40,A6) -> 0 | H6: % avaria | I6: =I4/I3 -> 0.02970297
A7: VLT-CAL-001-VIN-XP | B7: =_xlfn.XLOOKUP(A7,CATÁLOGO!$A$2:$A$846,CATÁLOGO!$B$2:$B$846,"FORA DO CATÁLOGO") -> CAL001H36 | C7: 1 | D7: =_xlfn.XLOOKUP(A7,CATÁLOGO!$A$2:$A$846,CATÁLOGO!$E$2:$E$846,"FORA DO CATÁLOGO") -> Fora do catálogo 2026 | E7: conferente: Jéssica | F7: =SUMIFS('AVARIA ESTIMADA'!$F$18:$F$40,'AVARIA ESTIMADA'!$A$18:$A$40,A7) -> 0 | H7: SKUs afetados | I7: =COUNTIF(F2:F731,">0") -> 20
A8: VLT-CAL-001-VIN-M | B8: =_xlfn.XLOOKUP(A8,CATÁLOGO!$A$2:$A$846,CATÁLOGO!$B$2:$B$846,"FORA DO CATÁLOGO") -> CAL001H40 | C8: 1 | D8: =_xlfn.XLOOKUP(A8,CATÁLOGO!$A$2:$A$846,CATÁLOGO!$E$2:$E$846,"FORA DO CATÁLOGO") -> Fora do catálogo 2026 | E8: conferente: Jéssica | SKU só na Eldorado – existe na lista 2024 (fora do catálogo 2026), mantido | F8: =SUMIFS('AVARIA ESTIMADA'!$F$18:$F$40,'AVARIA ESTIMADA'!$A$18:$A$40,A8) -> 0 | H8: % avaria – média das 4 lojas | I8: ='AVARIA ESTIMADA'!F14 -> 0.029957854
A9: VLT-CAL-001-VIN-GG | B9: =_xlfn.XLOOKUP(A9,CATÁLOGO!$A$2:$A$846,CATÁLOGO!$B$2:$B$846,"FORA DO CATÁLOGO") -> CAL001H44 | C9: 1 | D9: =_xlfn.XLOOKUP(A9,CATÁLOGO!$A$2:$A$846,CATÁLOGO!$E$2:$E$846,"FORA DO CATÁLOGO") -> Fora do catálogo 2026 | E9: conferente: Thiago | F9: =SUMIFS('AVARIA ESTIMADA'!$F$18:$F$40,'AVARIA ESTIMADA'!$A$18:$A$40,A9) -> 0
A10: VLT-TRI-003-PRE-G | B10: =_xlfn.XLOOKUP(A10,CATÁLOGO!$A$2:$A$846,CATÁLOGO!$B$2:$B$846,"FORA DO CATÁLOGO") -> FORA DO CATÁLOGO | C10: 1 | D10: =_xlfn.XLOOKUP(A10,CATÁLOGO!$A$2:$A$846,CATÁLOGO!$E$2:$E$846,"FORA DO CATÁLOGO") -> FORA DO CATÁLOGO | E10: conferente: Lari | código contado TRI003PG não existe (TRI-003 só em BEG/MRR na lista 2024) – mantido, não identificado | F10: =SUMIFS('AVARIA ESTIMADA'!$F$18:$F$40,'AVARIA ESTIMADA'!$A$18:$A$40,A10) -> 0 | H10: SKUs com avaria (maior → menor)
A11: VLT-SAI-001-BEG-M | B11: =_xlfn.XLOOKUP(A11,CATÁLOGO!$A$2:$A$846,CATÁLOGO!$B$2:$B$846,"FORA DO CATÁLOGO") -> SAI001GM | C11: 1 | D11: =_xlfn.XLOOKUP(A11,CATÁLOGO!$A$2:$A$846,CATÁLOGO!$E$2:$E$846,"FORA DO CATÁLOGO") -> Fora do catálogo 2026 | E11: conferente: Lari | SKU só na Eldorado – existe na lista 2024 (fora do catálogo 2026), mantido | F11: =SUMIFS('AVARIA ESTIMADA'!$F$18:$F$40,'AVARIA ESTIMADA'!$A$18:$A$40,A11) -> 0 | H11: SKU | I11: PEÇAS
A12: VLT-SAI-001-JCL-P | B12: =_xlfn.XLOOKUP(A12,CATÁLOGO!$A$2:$A$846,CATÁLOGO!$B$2:$B$846,"FORA DO CATÁLOGO") -> SAI001JP | C12: 1 | D12: =_xlfn.XLOOKUP(A12,CATÁLOGO!$A$2:$A$846,CATÁLOGO!$E$2:$E$846,"FORA DO CATÁLOGO") -> Fora do catálogo 2026 | E12: conferente: Jéssica | SKU só na Eldorado – existe na lista 2024 (fora do catálogo 2026), mantido | F12: =SUMIFS('AVARIA ESTIMADA'!$F$18:$F$40,'AVARIA ESTIMADA'!$A$18:$A$40,A12) -> 0 | H12: {=_xlfn._xlws.SORT(_xlfn._xlws.FILTER(_xlfn.HSTACK(A2:A731,F2:F731),F2:F731>0,"sem avaria"),2,-1)} -> VLT-CAL-003-PRE-G | I12: 6
A13: VLT-SAI-001-JCL-M | B13: =_xlfn.XLOOKUP(A13,CATÁLOGO!$A$2:$A$846,CATÁLOGO!$B$2:$B$846,"FORA DO CATÁLOGO") -> SAI001JM | C13: 1 | D13: =_xlfn.XLOOKUP(A13,CATÁLOGO!$A$2:$A$846,CATÁLOGO!$E$2:$E$846,"FORA DO CATÁLOGO") -> Fora do catálogo 2026 | E13: conferente: Jéssica | SKU só na Eldorado – existe na lista 2024 (fora do catálogo 2026), mantido | F13: =SUMIFS('AVARIA ESTIMADA'!$F$18:$F$40,'AVARIA ESTIMADA'!$A$18:$A$40,A13) -> 0 | H13: VLT-CAL-023-LIL-M | I13: 6
A14: VLT-BER-001-BRA-P | B14: =_xlfn.XLOOKUP(A14,CATÁLOGO!$A$2:$A$846,CATÁLOGO!$B$2:$B$846,"FORA DO CATÁLOGO") -> BER001B38 | C14: 6 | D14: =_xlfn.XLOOKUP(A14,CATÁLOGO!$A$2:$A$846,CATÁLOGO!$E$2:$E$846,"FORA DO CATÁLOGO") -> Ativo | E14: conferente: Thiago | F14: =SUMIFS('AVARIA ESTIMADA'!$F$18:$F$40,'AVARIA ESTIMADA'!$A$18:$A$40,A14) -> 0 | H14: VLT-TOP-006-MRR-G | I14: 5
A15: VLT-BER-001-BRA-M | B15: =_xlfn.XLOOKUP(A15,CATÁLOGO!$A$2:$A$846,CATÁLOGO!$B$2:$B$846,"FORA DO CATÁLOGO") -> BER001B40 | C15: 9 | D15: =_xlfn.XLOOKUP(A15,CATÁLOGO!$A$2:$A$846,CATÁLOGO!$E$2:$E$846,"FORA DO CATÁLOGO") -> Ativo | E15: conferente: Jéssica | F15: =SUMIFS('AVARIA ESTIMADA'!$F$18:$F$40,'AVARIA ESTIMADA'!$A$18:$A$40,A15) -> 0 | H15: VLT-CAL-011-LIL-P | I15: 5
A16: VLT-BER-001-BRA-G | B16: =_xlfn.XLOOKUP(A16,CATÁLOGO!$A$2:$A$846,CATÁLOGO!$B$2:$B$846,"FORA DO CATÁLOGO") -> BER001B42 | C16: 6 | D16: =_xlfn.XLOOKUP(A16,CATÁLOGO!$A$2:$A$846,CATÁLOGO!$E$2:$E$846,"FORA DO CATÁLOGO") -> Ativo | E16: conferente: Jéssica | F16: =SUMIFS('AVARIA ESTIMADA'!$F$18:$F$40,'AVARIA ESTIMADA'!$A$18:$A$40,A16) -> 0 | H16: VLT-CAL-024-AZM-P | I16: 5
A17: VLT-BER-001-BRA-GG | B17: =_xlfn.XLOOKUP(A17,CATÁLOGO!$A$2:$A$846,CATÁLOGO!$B$2:$B$846,"FORA DO CATÁLOGO") -> BER001B44 | C17: 3 | D17: =_xlfn.XLOOKUP(A17,CATÁLOGO!$A$2:$A$846,CATÁLOGO!$E$2:$E$846,"FORA DO CATÁLOGO") -> Ativo | E17: conferente: Thiago | F17: =SUMIFS('AVARIA ESTIMADA'!$F$18:$F$40,'AVARIA ESTIMADA'!$A$18:$A$40,A17) -> 0 | H17: VLT-TOP-001-AMA-G | I17: 5
A18: VLT-CAL-003-PRE-P | B18: =_xlfn.XLOOKUP(A18,CATÁLOGO!$A$2:$A$846,CATÁLOGO!$B$2:$B$846,"FORA DO CATÁLOGO") -> CAL003P38 | C18: 6 | D18: =_xlfn.XLOOKUP(A18,CATÁLOGO!$A$2:$A$846,CATÁLOGO!$E$2:$E$846,"FORA DO CATÁLOGO") -> Ativo | E18: conferente: Jéssica | F18: =SUMIFS('AVARIA ESTIMADA'!$F$18:$F$40,'AVARIA ESTIMADA'!$A$18:$A$40,A18) -> 0 | H18: VLT-VES-006-MRR-G | I18: 4
A19: VLT-CAL-003-PRE-M | B19: =_xlfn.XLOOKUP(A19,CATÁLOGO!$A$2:$A$846,CATÁLOGO!$B$2:$B$846,"FORA DO CATÁLOGO") -> CAL003P40 | C19: 6 | D19: =_xlfn.XLOOKUP(A19,CATÁLOGO!$A$2:$A$846,CATÁLOGO!$E$2:$E$846,"FORA DO CATÁLOGO") -> Ativo | E19: conferente: Lari | F19: =SUMIFS('AVARIA ESTIMADA'!$F$18:$F$40,'AVARIA ESTIMADA'!$A$18:$A$40,A19) -> 0 | H19: VLT-BER-007-AZM-G | I19: 4
A20: VLT-CAL-003-PRE-G | B20: =_xlfn.XLOOKUP(A20,CATÁLOGO!$A$2:$A$846,CATÁLOGO!$B$2:$B$846,"FORA DO CATÁLOGO") -> CAL003P42 | C20: 6 | D20: =_xlfn.XLOOKUP(A20,CATÁLOGO!$A$2:$A$846,CATÁLOGO!$E$2:$E$846,"FORA DO CATÁLOGO") -> Ativo | E20: conferente: Lari | F20: =SUMIFS('AVARIA ESTIMADA'!$F$18:$F$40,'AVARIA ESTIMADA'!$A$18:$A$40,A20) -> 6 | H20: VLT-CAM-017-AMA-G | I20: 4
A21: VLT-CAL-003-PRE-GG | B21: =_xlfn.XLOOKUP(A21,CATÁLOGO!$A$2:$A$846,CATÁLOGO!$B$2:$B$846,"FORA DO CATÁLOGO") -> CAL003P44 | C21: 3 | D21: =_xlfn.XLOOKUP(A21,CATÁLOGO!$A$2:$A$846,CATÁLOGO!$E$2:$E$846,"FORA DO CATÁLOGO") -> Ativo | E21: conferente: Jéssica | F21: =SUMIFS('AVARIA ESTIMADA'!$F$18:$F$40,'AVARIA ESTIMADA'!$A$18:$A$40,A21) -> 0 | H21: VLT-CAM-020-AMA-P | I21: 4
A22: VLT-CAL-004-CIN-XP | B22: =_xlfn.XLOOKUP(A22,CATÁLOGO!$A$2:$A$846,CATÁLOGO!$B$2:$B$846,"FORA DO CATÁLOGO") -> CAL004C36 | C22: 1 | D22: =_xlfn.XLOOKUP(A22,CATÁLOGO!$A$2:$A$846,CATÁLOGO!$E$2:$E$846,"FORA DO CATÁLOGO") -> Ativo | E22: conferente: Jéssica | F22: =SUMIFS('AVARIA ESTIMADA'!$F$18:$F$40,'AVARIA ESTIMADA'!$A$18:$A$40,A22) -> 0 | H22: VLT-CAM-020-AMA-G | I22: 4
A23: VLT-CAL-004-CIN-P | B23: =_xlfn.XLOOKUP(A23,CATÁLOGO!$A$2:$A$846,CATÁLOGO!$B$2:$B$846,"FORA DO CATÁLOGO") -> CAL004C38 | C23: 1 | D23: =_xlfn.XLOOKUP(A23,CATÁLOGO!$A$2:$A$846,CATÁLOGO!$E$2:$E$846,"FORA DO CATÁLOGO") -> Ativo | E23: conferente: Lari | F23: =SUMIFS('AVARIA ESTIMADA'!$F$18:$F$40,'AVARIA ESTIMADA'!$A$18:$A$40,A23) -> 0 | H23: VLT-VES-009-BEG-G | I23: 3
A24: VLT-CAL-004-CIN-M | B24: =_xlfn.XLOOKUP(A24,CATÁLOGO!$A$2:$A$846,CATÁLOGO!$B$2:$B$846,"FORA DO CATÁLOGO") -> CAL004C40 | C24: 2 | D24: =_xlfn.XLOOKUP(A24,CATÁLOGO!$A$2:$A$846,CATÁLOGO!$E$2:$E$846,"FORA DO CATÁLOGO") -> Ativo | E24: conferente: Thiago | F24: =SUMIFS('AVARIA ESTIMADA'!$F$18:$F$40,'AVARIA ESTIMADA'!$A$18:$A$40,A24) -> 0 | H24: VLT-CAM-004-PRE-M | I24: 2
... A31: VLT-CAL-004-BEG-XG | B31: =_xlfn.XLOOKUP(A31,CATÁLOGO!$A$2:$A$846,CATÁLOGO!$B$2:$B$846,"FORA DO CATÁLOGO") -> CAL004G46 | C31: 1 | D31: =_xlfn.XLOOKUP(A31,CATÁLOGO!$A$2:$A$846,CATÁLOGO!$E$2:$E$846,"FORA DO CATÁLOGO") -> Ativo | E31: conferente: Lari | F31: =SUMIFS('AVARIA ESTIMADA'!$F$18:$F$40,'AVARIA ESTIMADA'!$A$18:$A$40,A31) -> 0 | H31: VLT-SAI-009-BRA-P | I31: 1
A32: VLT-CAL-005-PRE-XP | B32: =_xlfn.XLOOKUP(A32,CATÁLOGO!$A$2:$A$846,CATÁLOGO!$B$2:$B$846,"FORA DO CATÁLOGO") -> CAL005P36 | C32: 3 | D32: =_xlfn.XLOOKUP(A32,CATÁLOGO!$A$2:$A$846,CATÁLOGO!$E$2:$E$846,"FORA DO CATÁLOGO") -> Ativo | E32: conferente: Lari | F32: =SUMIFS('AVARIA ESTIMADA'!$F$18:$F$40,'AVARIA ESTIMADA'!$A$18:$A$40,A32) -> 0
A33: VLT-CAL-005-PRE-P | B33: =_xlfn.XLOOKUP(A33,CATÁLOGO!$A$2:$A$846,CATÁLOGO!$B$2:$B$846,"FORA DO CATÁLOGO") -> CAL005P38 | C33: 6 | D33: =_xlfn.XLOOKUP(A33,CATÁLOGO!$A$2:$A$846,CATÁLOGO!$E$2:$E$846,"FORA DO CATÁLOGO") -> Ativo | E33: conferente: Jéssica | F33: =SUMIFS('AVARIA ESTIMADA'!$F$18:$F$40,'AVARIA ESTIMADA'!$A$18:$A$40,A33) -> 0
A34: VLT-CAL-005-PRE-M | B34: =_xlfn.XLOOKUP(A34,CATÁLOGO!$A$2:$A$846,CATÁLOGO!$B$2:$B$846,"FORA DO CATÁLOGO") -> CAL005P40 | C34: 6 | D34: =_xlfn.XLOOKUP(A34,CATÁLOGO!$A$2:$A$846,CATÁLOGO!$E$2:$E$846,"FORA DO CATÁLOGO") -> Ativo | E34: conferente: Thiago | F34: =SUMIFS('AVARIA ESTIMADA'!$F$18:$F$40,'AVARIA ESTIMADA'!$A$18:$A$40,A34) -> 0
A35: VLT-CAL-005-PRE-G | B35: =_xlfn.XLOOKUP(A35,CATÁLOGO!$A$2:$A$846,CATÁLOGO!$B$2:$B$846,"FORA DO CATÁLOGO") -> CAL005P42 | C35: 6 | D35: =_xlfn.XLOOKUP(A35,CATÁLOGO!$A$2:$A$846,CATÁLOGO!$E$2:$E$846,"FORA DO CATÁLOGO") -> Ativo | E35: conferente: Thiago | F35: =SUMIFS('AVARIA ESTIMADA'!$F$18:$F$40,'AVARIA ESTIMADA'!$A$18:$A$40,A35) -> 0
A36: VLT-CAL-005-PRE-GG | B36: =_xlfn.XLOOKUP(A36,CATÁLOGO!$A$2:$A$846,CATÁLOGO!$B$2:$B$846,"FORA DO CATÁLOGO") -> CAL005P44 | C36: 3 | D36: =_xlfn.XLOOKUP(A36,CATÁLOGO!$A$2:$A$846,CATÁLOGO!$E$2:$E$846,"FORA DO CATÁLOGO") -> Ativo | E36: conferente: Thiago | F36: =SUMIFS('AVARIA ESTIMADA'!$F$18:$F$40,'AVARIA ESTIMADA'!$A$18:$A$40,A36) -> 0
A37: VLT-TOP-002-AZM-P | B37: =_xlfn.XLOOKUP(A37,CATÁLOGO!$A$2:$A$846,CATÁLOGO!$B$2:$B$846,"FORA DO CATÁLOGO") -> TOP002AP | C37: 3 | D37: =_xlfn.XLOOKUP(A37,CATÁLOGO!$A$2:$A$846,CATÁLOGO!$E$2:$E$846,"FORA DO CATÁLOGO") -> Ativo | E37: conferente: Lari | F37: =SUMIFS('AVARIA ESTIMADA'!$F$18:$F$40,'AVARIA ESTIMADA'!$A$18:$A$40,A37) -> 0
A38: VLT-TOP-002-AZM-M | B38: =_xlfn.XLOOKUP(A38,CATÁLOGO!$A$2:$A$846,CATÁLOGO!$B$2:$B$846,"FORA DO CATÁLOGO") -> TOP002AM | C38: 5 | D38: =_xlfn.XLOOKUP(A38,CATÁLOGO!$A$2:$A$846,CATÁLOGO!$E$2:$E$846,"FORA DO CATÁLOGO") -> Ativo | E38: conferente: Thiago | F38: =SUMIFS('AVARIA ESTIMADA'!$F$18:$F$40,'AVARIA ESTIMADA'!$A$18:$A$40,A38) -> 0
A39: VLT-TOP-002-AZM-G | B39: =_xlfn.XLOOKUP(A39,CATÁLOGO!$A$2:$A$846,CATÁLOGO!$B$2:$B$846,"FORA DO CATÁLOGO") -> TOP002AG | C39: 4 | D39: =_xlfn.XLOOKUP(A39,CATÁLOGO!$A$2:$A$846,CATÁLOGO!$E$2:$E$846,"FORA DO CATÁLOGO") -> Ativo | E39: conferente: Jéssica | F39: =SUMIFS('AVARIA ESTIMADA'!$F$18:$F$40,'AVARIA ESTIMADA'!$A$18:$A$40,A39) -> 0
A40: VLT-TOP-002-AZM-GG | B40: =_xlfn.XLOOKUP(A40,CATÁLOGO!$A$2:$A$846,CATÁLOGO!$B$2:$B$846,"FORA DO CATÁLOGO") -> TOP002AGG | C40: 2 | D40: =_xlfn.XLOOKUP(A40,CATÁLOGO!$A$2:$A$846,CATÁLOGO!$E$2:$E$846,"FORA DO CATÁLOGO") -> Ativo | E40: conferente: Jéssica | F40: =SUMIFS('AVARIA ESTIMADA'!$F$18:$F$40,'AVARIA ESTIMADA'!$A$18:$A$40,A40) -> 0
A41: VLT-TOP-002-PRE-M | B41: =_xlfn.XLOOKUP(A41,CATÁLOGO!$A$2:$A$846,CATÁLOGO!$B$2:$B$846,"FORA DO CATÁLOGO") -> TOP002PM | C41: 2 | D41: =_xlfn.XLOOKUP(A41,CATÁLOGO!$A$2:$A$846,CATÁLOGO!$E$2:$E$846,"FORA DO CATÁLOGO") -> Descontinuado | E41: conferente: Thiago | SKU só na Eldorado – existe no catálogo (descontinuado), mantido | F41: =SUMIFS('AVARIA ESTIMADA'!$F$18:$F$40,'AVARIA ESTIMADA'!$A$18:$A$40,A41) -> 0
A42: VLT-TOP-002-PRE-G | B42: =_xlfn.XLOOKUP(A42,CATÁLOGO!$A$2:$A$846,CATÁLOGO!$B$2:$B$846,"FORA DO CATÁLOGO") -> TOP002PG | C42: 1 | D42: =_xlfn.XLOOKUP(A42,CATÁLOGO!$A$2:$A$846,CATÁLOGO!$E$2:$E$846,"FORA DO CATÁLOGO") -> Descontinuado | E42: conferente: Jéssica | F42: =SUMIFS('AVARIA ESTIMADA'!$F$18:$F$40,'AVARIA ESTIMADA'!$A$18:$A$40,A42) -> 0
A43: VLT-TOP-002-PRE-GG | B43: =_xlfn.XLOOKUP(A43,CATÁLOGO!$A$2:$A$846,CATÁLOGO!$B$2:$B$846,"FORA DO CATÁLOGO") -> TOP002PGG | C43: 1 | D43: =_xlfn.XLOOKUP(A43,CATÁLOGO!$A$2:$A$846,CATÁLOGO!$E$2:$E$846,"FORA DO CATÁLOGO") -> Descontinuado | E43: conferente: Jéssica | F43: =SUMIFS('AVARIA ESTIMADA'!$F$18:$F$40,'AVARIA ESTIMADA'!$A$18:$A$40,A43) -> 0
... A731: VLT-JAQ-011-OLI-GG | B731: =_xlfn.XLOOKUP(A731,CATÁLOGO!$A$2:$A$846,CATÁLOGO!$B$2:$B$846,"FORA DO CATÁLOGO") -> JAQ011VGG | C731: 3 | D731: =_xlfn.XLOOKUP(A731,CATÁLOGO!$A$2:$A$846,CATÁLOGO!$E$2:$E$846,"FORA DO CATÁLOGO") -> Ativo | E731: conferente: Lari | F731: =SUMIFS('AVARIA ESTIMADA'!$F$18:$F$40,'AVARIA ESTIMADA'!$A$18:$A$40,A731) -> 0

Sheet SAVASSI
A1: SKU | B1: CÓDIGO CD | C1: QTD | D1: STATUS CATÁLOGO | E1: OBS | F1: AVARIA EST. | H1: RESUMO AVARIA – SAVASSI
A2: VLT-CAL-001-VIN-G | B2: =_xlfn.XLOOKUP(A2,CATÁLOGO!$A$2:$A$846,CATÁLOGO!$B$2:$B$846,"FORA DO CATÁLOGO") -> CAL001H42 | C2: 1 | D2: =_xlfn.XLOOKUP(A2,CATÁLOGO!$A$2:$A$846,CATÁLOGO!$E$2:$E$846,"FORA DO CATÁLOGO") -> Fora do catálogo 2026 | E2: ESTOQUE SIMULADO | F2: =SUMIFS('AVARIA ESTIMADA'!$H$18:$H$40,'AVARIA ESTIMADA'!$A$18:$A$40,A2) -> 0 | H2: Tipo de avaria | I2: Estimada (decisão 13)
A3: VLT-BER-001-BRA-P | B3: =_xlfn.XLOOKUP(A3,CATÁLOGO!$A$2:$A$846,CATÁLOGO!$B$2:$B$846,"FORA DO CATÁLOGO") -> BER001B38 | C3: 6 | D3: =_xlfn.XLOOKUP(A3,CATÁLOGO!$A$2:$A$846,CATÁLOGO!$E$2:$E$846,"FORA DO CATÁLOGO") -> Ativo | E3: ESTOQUE SIMULADO | F3: =SUMIFS('AVARIA ESTIMADA'!$H$18:$H$40,'AVARIA ESTIMADA'!$A$18:$A$40,A3) -> 0 | H3: Estoque contado (inclui avaria) | I3: =SUM(C2:C720) -> 2114
A4: VLT-BER-001-BRA-M | B4: =_xlfn.XLOOKUP(A4,CATÁLOGO!$A$2:$A$846,CATÁLOGO!$B$2:$B$846,"FORA DO CATÁLOGO") -> BER001B40 | C4: 5 | D4: =_xlfn.XLOOKUP(A4,CATÁLOGO!$A$2:$A$846,CATÁLOGO!$E$2:$E$846,"FORA DO CATÁLOGO") -> Ativo | E4: ESTOQUE SIMULADO | F4: =SUMIFS('AVARIA ESTIMADA'!$H$18:$H$40,'AVARIA ESTIMADA'!$A$18:$A$40,A4) -> 0 | H4: Peças com avaria | I4: =SUM(F2:F720) -> 65
A5: VLT-BER-001-BRA-G | B5: =_xlfn.XLOOKUP(A5,CATÁLOGO!$A$2:$A$846,CATÁLOGO!$B$2:$B$846,"FORA DO CATÁLOGO") -> BER001B42 | C5: 5 | D5: =_xlfn.XLOOKUP(A5,CATÁLOGO!$A$2:$A$846,CATÁLOGO!$E$2:$E$846,"FORA DO CATÁLOGO") -> Ativo | E5: ESTOQUE SIMULADO | F5: =SUMIFS('AVARIA ESTIMADA'!$H$18:$H$40,'AVARIA ESTIMADA'!$A$18:$A$40,A5) -> 0 | H5: Estoque vendável | I5: =I3-I4 -> 2049
A6: VLT-BER-001-BRA-GG | B6: =_xlfn.XLOOKUP(A6,CATÁLOGO!$A$2:$A$846,CATÁLOGO!$B$2:$B$846,"FORA DO CATÁLOGO") -> BER001B44 | C6: 4 | D6: =_xlfn.XLOOKUP(A6,CATÁLOGO!$A$2:$A$846,CATÁLOGO!$E$2:$E$846,"FORA DO CATÁLOGO") -> Ativo | E6: ESTOQUE SIMULADO | F6: =SUMIFS('AVARIA ESTIMADA'!$H$18:$H$40,'AVARIA ESTIMADA'!$A$18:$A$40,A6) -> 0 | H6: % avaria | I6: =I4/I3 -> 0.030747398
A7: VLT-CAL-003-PRE-P | B7: =_xlfn.XLOOKUP(A7,CATÁLOGO!$A$2:$A$846,CATÁLOGO!$B$2:$B$846,"FORA DO CATÁLOGO") -> CAL003P38 | C7: 5 | D7: =_xlfn.XLOOKUP(A7,CATÁLOGO!$A$2:$A$846,CATÁLOGO!$E$2:$E$846,"FORA DO CATÁLOGO") -> Ativo | E7: ESTOQUE SIMULADO | F7: =SUMIFS('AVARIA ESTIMADA'!$H$18:$H$40,'AVARIA ESTIMADA'!$A$18:$A$40,A7) -> 0 | H7: SKUs afetados | I7: =COUNTIF(F2:F720,">0") -> 22
A8: VLT-CAL-003-PRE-M | B8: =_xlfn.XLOOKUP(A8,CATÁLOGO!$A$2:$A$846,CATÁLOGO!$B$2:$B$846,"FORA DO CATÁLOGO") -> CAL003P40 | C8: 5 | D8: =_xlfn.XLOOKUP(A8,CATÁLOGO!$A$2:$A$846,CATÁLOGO!$E$2:$E$846,"FORA DO CATÁLOGO") -> Ativo | E8: ESTOQUE SIMULADO | F8: =SUMIFS('AVARIA ESTIMADA'!$H$18:$H$40,'AVARIA ESTIMADA'!$A$18:$A$40,A8) -> 0 | H8: % avaria – média das 4 lojas | I8: ='AVARIA ESTIMADA'!F14 -> 0.029957854
A9: VLT-CAL-003-PRE-G | B9: =_xlfn.XLOOKUP(A9,CATÁLOGO!$A$2:$A$846,CATÁLOGO!$B$2:$B$846,"FORA DO CATÁLOGO") -> CAL003P42 | C9: 5 | D9: =_xlfn.XLOOKUP(A9,CATÁLOGO!$A$2:$A$846,CATÁLOGO!$E$2:$E$846,"FORA DO CATÁLOGO") -> Ativo | E9: ESTOQUE SIMULADO | F9: =SUMIFS('AVARIA ESTIMADA'!$H$18:$H$40,'AVARIA ESTIMADA'!$A$18:$A$40,A9) -> 5
A10: VLT-CAL-003-PRE-GG | B10: =_xlfn.XLOOKUP(A10,CATÁLOGO!$A$2:$A$846,CATÁLOGO!$B$2:$B$846,"FORA DO CATÁLOGO") -> CAL003P44 | C10: 3 | D10: =_xlfn.XLOOKUP(A10,CATÁLOGO!$A$2:$A$846,CATÁLOGO!$E$2:$E$846,"FORA DO CATÁLOGO") -> Ativo | E10: ESTOQUE SIMULADO | F10: =SUMIFS('AVARIA ESTIMADA'!$H$18:$H$40,'AVARIA ESTIMADA'!$A$18:$A$40,A10) -> 0 | H10: SKUs com avaria (maior → menor)
A11: VLT-CAL-004-CIN-XP | B11: =_xlfn.XLOOKUP(A11,CATÁLOGO!$A$2:$A$846,CATÁLOGO!$B$2:$B$846,"FORA DO CATÁLOGO") -> CAL004C36 | C11: 1 | D11: =_xlfn.XLOOKUP(A11,CATÁLOGO!$A$2:$A$846,CATÁLOGO!$E$2:$E$846,"FORA DO CATÁLOGO") -> Ativo | E11: ESTOQUE SIMULADO | F11: =SUMIFS('AVARIA ESTIMADA'!$H$18:$H$40,'AVARIA ESTIMADA'!$A$18:$A$40,A11) -> 0 | H11: SKU | I11: PEÇAS
A12: VLT-CAL-004-CIN-P | B12: =_xlfn.XLOOKUP(A12,CATÁLOGO!$A$2:$A$846,CATÁLOGO!$B$2:$B$846,"FORA DO CATÁLOGO") -> CAL004C38 | C12: 3 | D12: =_xlfn.XLOOKUP(A12,CATÁLOGO!$A$2:$A$846,CATÁLOGO!$E$2:$E$846,"FORA DO CATÁLOGO") -> Ativo | E12: ESTOQUE SIMULADO | F12: =SUMIFS('AVARIA ESTIMADA'!$H$18:$H$40,'AVARIA ESTIMADA'!$A$18:$A$40,A12) -> 0 | H12: {=_xlfn._xlws.SORT(_xlfn._xlws.FILTER(_xlfn.HSTACK(A2:A720,F2:F720),F2:F720>0,"sem avaria"),2,-1)} -> VLT-CAL-023-LIL-M | I12: 6
A13: VLT-CAL-004-CIN-M | B13: =_xlfn.XLOOKUP(A13,CATÁLOGO!$A$2:$A$846,CATÁLOGO!$B$2:$B$846,"FORA DO CATÁLOGO") -> CAL004C40 | C13: 3 | D13: =_xlfn.XLOOKUP(A13,CATÁLOGO!$A$2:$A$846,CATÁLOGO!$E$2:$E$846,"FORA DO CATÁLOGO") -> Ativo | E13: ESTOQUE SIMULADO | F13: =SUMIFS('AVARIA ESTIMADA'!$H$18:$H$40,'AVARIA ESTIMADA'!$A$18:$A$40,A13) -> 0 | H13: VLT-CAL-003-PRE-G | I13: 5
A14: VLT-CAL-004-CIN-G | B14: =_xlfn.XLOOKUP(A14,CATÁLOGO!$A$2:$A$846,CATÁLOGO!$B$2:$B$846,"FORA DO CATÁLOGO") -> CAL004C42 | C14: 2 | D14: =_xlfn.XLOOKUP(A14,CATÁLOGO!$A$2:$A$846,CATÁLOGO!$E$2:$E$846,"FORA DO CATÁLOGO") -> Ativo | E14: ESTOQUE SIMULADO | F14: =SUMIFS('AVARIA ESTIMADA'!$H$18:$H$40,'AVARIA ESTIMADA'!$A$18:$A$40,A14) -> 0 | H14: VLT-TOP-006-MRR-G | I14: 4
A15: VLT-CAL-004-CIN-GG | B15: =_xlfn.XLOOKUP(A15,CATÁLOGO!$A$2:$A$846,CATÁLOGO!$B$2:$B$846,"FORA DO CATÁLOGO") -> CAL004C44 | C15: 1 | D15: =_xlfn.XLOOKUP(A15,CATÁLOGO!$A$2:$A$846,CATÁLOGO!$E$2:$E$846,"FORA DO CATÁLOGO") -> Ativo | E15: ESTOQUE SIMULADO | F15: =SUMIFS('AVARIA ESTIMADA'!$H$18:$H$40,'AVARIA ESTIMADA'!$A$18:$A$40,A15) -> 0 | H15: VLT-CAL-011-LIL-P | I15: 4
A16: VLT-CAL-004-CIN-XG | B16: =_xlfn.XLOOKUP(A16,CATÁLOGO!$A$2:$A$846,CATÁLOGO!$B$2:$B$846,"FORA DO CATÁLOGO") -> CAL004C46 | C16: 1 | D16: =_xlfn.XLOOKUP(A16,CATÁLOGO!$A$2:$A$846,CATÁLOGO!$E$2:$E$846,"FORA DO CATÁLOGO") -> Ativo | E16: ESTOQUE SIMULADO | F16: =SUMIFS('AVARIA ESTIMADA'!$H$18:$H$40,'AVARIA ESTIMADA'!$A$18:$A$40,A16) -> 0 | H16: VLT-CAL-024-AZM-P | I16: 4
A17: VLT-CAL-004-BEG-XP | B17: =_xlfn.XLOOKUP(A17,CATÁLOGO!$A$2:$A$846,CATÁLOGO!$B$2:$B$846,"FORA DO CATÁLOGO") -> CAL004G36 | C17: 1 | D17: =_xlfn.XLOOKUP(A17,CATÁLOGO!$A$2:$A$846,CATÁLOGO!$E$2:$E$846,"FORA DO CATÁLOGO") -> Ativo | E17: ESTOQUE SIMULADO | F17: =SUMIFS('AVARIA ESTIMADA'!$H$18:$H$40,'AVARIA ESTIMADA'!$A$18:$A$40,A17) -> 0 | H17: VLT-TOP-001-AMA-G | I17: 4
A18: VLT-CAL-004-BEG-M | B18: =_xlfn.XLOOKUP(A18,CATÁLOGO!$A$2:$A$846,CATÁLOGO!$B$2:$B$846,"FORA DO CATÁLOGO") -> CAL004G40 | C18: 1 | D18: =_xlfn.XLOOKUP(A18,CATÁLOGO!$A$2:$A$846,CATÁLOGO!$E$2:$E$846,"FORA DO CATÁLOGO") -> Ativo | E18: ESTOQUE SIMULADO | F18: =SUMIFS('AVARIA ESTIMADA'!$H$18:$H$40,'AVARIA ESTIMADA'!$A$18:$A$40,A18) -> 0 | H18: VLT-CAM-020-AMA-G | I18: 4
A19: VLT-CAL-004-BEG-G | B19: =_xlfn.XLOOKUP(A19,CATÁLOGO!$A$2:$A$846,CATÁLOGO!$B$2:$B$846,"FORA DO CATÁLOGO") -> CAL004G42 | C19: 1 | D19: =_xlfn.XLOOKUP(A19,CATÁLOGO!$A$2:$A$846,CATÁLOGO!$E$2:$E$846,"FORA DO CATÁLOGO") -> Ativo | E19: ESTOQUE SIMULADO | F19: =SUMIFS('AVARIA ESTIMADA'!$H$18:$H$40,'AVARIA ESTIMADA'!$A$18:$A$40,A19) -> 0 | H19: VLT-VES-006-MRR-G | I19: 3
A20: VLT-CAL-004-BEG-GG | B20: =_xlfn.XLOOKUP(A20,CATÁLOGO!$A$2:$A$846,CATÁLOGO!$B$2:$B$846,"FORA DO CATÁLOGO") -> CAL004G44 | C20: 0 | D20: =_xlfn.XLOOKUP(A20,CATÁLOGO!$A$2:$A$846,CATÁLOGO!$E$2:$E$846,"FORA DO CATÁLOGO") -> Ativo | E20: ESTOQUE SIMULADO | F20: =SUMIFS('AVARIA ESTIMADA'!$H$18:$H$40,'AVARIA ESTIMADA'!$A$18:$A$40,A20) -> 0 | H20: VLT-CAL-016-OLI-P | I20: 3
A21: VLT-CAL-005-PRE-XP | B21: =_xlfn.XLOOKUP(A21,CATÁLOGO!$A$2:$A$846,CATÁLOGO!$B$2:$B$846,"FORA DO CATÁLOGO") -> CAL005P36 | C21: 4 | D21: =_xlfn.XLOOKUP(A21,CATÁLOGO!$A$2:$A$846,CATÁLOGO!$E$2:$E$846,"FORA DO CATÁLOGO") -> Ativo | E21: ESTOQUE SIMULADO | F21: =SUMIFS('AVARIA ESTIMADA'!$H$18:$H$40,'AVARIA ESTIMADA'!$A$18:$A$40,A21) -> 0 | H21: VLT-CAL-016-OLI-M | I21: 3
A22: VLT-CAL-005-PRE-P | B22: =_xlfn.XLOOKUP(A22,CATÁLOGO!$A$2:$A$846,CATÁLOGO!$B$2:$B$846,"FORA DO CATÁLOGO") -> CAL005P38 | C22: 5 | D22: =_xlfn.XLOOKUP(A22,CATÁLOGO!$A$2:$A$846,CATÁLOGO!$E$2:$E$846,"FORA DO CATÁLOGO") -> Ativo | E22: ESTOQUE SIMULADO | F22: =SUMIFS('AVARIA ESTIMADA'!$H$18:$H$40,'AVARIA ESTIMADA'!$A$18:$A$40,A22) -> 0 | H22: VLT-BER-007-AZM-G | I22: 3
A23: VLT-CAL-005-PRE-M | B23: =_xlfn.XLOOKUP(A23,CATÁLOGO!$A$2:$A$846,CATÁLOGO!$B$2:$B$846,"FORA DO CATÁLOGO") -> CAL005P40 | C23: 5 | D23: =_xlfn.XLOOKUP(A23,CATÁLOGO!$A$2:$A$846,CATÁLOGO!$E$2:$E$846,"FORA DO CATÁLOGO") -> Ativo | E23: ESTOQUE SIMULADO | F23: =SUMIFS('AVARIA ESTIMADA'!$H$18:$H$40,'AVARIA ESTIMADA'!$A$18:$A$40,A23) -> 0 | H23: VLT-CAM-017-AMA-G | I23: 3
A24: VLT-CAL-005-PRE-G | B24: =_xlfn.XLOOKUP(A24,CATÁLOGO!$A$2:$A$846,CATÁLOGO!$B$2:$B$846,"FORA DO CATÁLOGO") -> CAL005P42 | C24: 4 | D24: =_xlfn.XLOOKUP(A24,CATÁLOGO!$A$2:$A$846,CATÁLOGO!$E$2:$E$846,"FORA DO CATÁLOGO") -> Ativo | E24: ESTOQUE SIMULADO | F24: =SUMIFS('AVARIA ESTIMADA'!$H$18:$H$40,'AVARIA ESTIMADA'!$A$18:$A$40,A24) -> 0 | H24: VLT-VES-009-BEG-G | I24: 3
... A33: VLT-BER-002-CIN-P | B33: =_xlfn.XLOOKUP(A33,CATÁLOGO!$A$2:$A$846,CATÁLOGO!$B$2:$B$846,"FORA DO CATÁLOGO") -> BER002C38 | C33: 2 | D33: =_xlfn.XLOOKUP(A33,CATÁLOGO!$A$2:$A$846,CATÁLOGO!$E$2:$E$846,"FORA DO CATÁLOGO") -> Ativo | E33: ESTOQUE SIMULADO | F33: =SUMIFS('AVARIA ESTIMADA'!$H$18:$H$40,'AVARIA ESTIMADA'!$A$18:$A$40,A33) -> 0 | H33: VLT-TOP-010-AMA-M | I33: 1
A34: VLT-BER-002-CIN-M | B34: =_xlfn.XLOOKUP(A34,CATÁLOGO!$A$2:$A$846,CATÁLOGO!$B$2:$B$846,"FORA DO CATÁLOGO") -> BER002C40 | C34: 2 | D34: =_xlfn.XLOOKUP(A34,CATÁLOGO!$A$2:$A$846,CATÁLOGO!$E$2:$E$846,"FORA DO CATÁLOGO") -> Ativo | E34: ESTOQUE SIMULADO | F34: =SUMIFS('AVARIA ESTIMADA'!$H$18:$H$40,'AVARIA ESTIMADA'!$A$18:$A$40,A34) -> 0
A35: VLT-BER-002-CIN-G | B35: =_xlfn.XLOOKUP(A35,CATÁLOGO!$A$2:$A$846,CATÁLOGO!$B$2:$B$846,"FORA DO CATÁLOGO") -> BER002C42 | C35: 1 | D35: =_xlfn.XLOOKUP(A35,CATÁLOGO!$A$2:$A$846,CATÁLOGO!$E$2:$E$846,"FORA DO CATÁLOGO") -> Ativo | E35: ESTOQUE SIMULADO | F35: =SUMIFS('AVARIA ESTIMADA'!$H$18:$H$40,'AVARIA ESTIMADA'!$A$18:$A$40,A35) -> 0
A36: VLT-BER-002-CIN-GG | B36: =_xlfn.XLOOKUP(A36,CATÁLOGO!$A$2:$A$846,CATÁLOGO!$B$2:$B$846,"FORA DO CATÁLOGO") -> BER002C44 | C36: 1 | D36: =_xlfn.XLOOKUP(A36,CATÁLOGO!$A$2:$A$846,CATÁLOGO!$E$2:$E$846,"FORA DO CATÁLOGO") -> Ativo | E36: ESTOQUE SIMULADO | F36: =SUMIFS('AVARIA ESTIMADA'!$H$18:$H$40,'AVARIA ESTIMADA'!$A$18:$A$40,A36) -> 0
A37: VLT-BER-003-BRA-XP | B37: =_xlfn.XLOOKUP(A37,CATÁLOGO!$A$2:$A$846,CATÁLOGO!$B$2:$B$846,"FORA DO CATÁLOGO") -> BER003B36 | C37: 3 | D37: =_xlfn.XLOOKUP(A37,CATÁLOGO!$A$2:$A$846,CATÁLOGO!$E$2:$E$846,"FORA DO CATÁLOGO") -> Ativo | E37: ESTOQUE SIMULADO | F37: =SUMIFS('AVARIA ESTIMADA'!$H$18:$H$40,'AVARIA ESTIMADA'!$A$18:$A$40,A37) -> 0
A38: VLT-BER-003-BRA-P | B38: =_xlfn.XLOOKUP(A38,CATÁLOGO!$A$2:$A$846,CATÁLOGO!$B$2:$B$846,"FORA DO CATÁLOGO") -> BER003B38 | C38: 5 | D38: =_xlfn.XLOOKUP(A38,CATÁLOGO!$A$2:$A$846,CATÁLOGO!$E$2:$E$846,"FORA DO CATÁLOGO") -> Ativo | E38: ESTOQUE SIMULADO | F38: =SUMIFS('AVARIA ESTIMADA'!$H$18:$H$40,'AVARIA ESTIMADA'!$A$18:$A$40,A38) -> 0
A39: VLT-BER-003-BRA-M | B39: =_xlfn.XLOOKUP(A39,CATÁLOGO!$A$2:$A$846,CATÁLOGO!$B$2:$B$846,"FORA DO CATÁLOGO") -> BER003B40 | C39: 4 | D39: =_xlfn.XLOOKUP(A39,CATÁLOGO!$A$2:$A$846,CATÁLOGO!$E$2:$E$846,"FORA DO CATÁLOGO") -> Ativo | E39: ESTOQUE SIMULADO | F39: =SUMIFS('AVARIA ESTIMADA'!$H$18:$H$40,'AVARIA ESTIMADA'!$A$18:$A$40,A39) -> 0
A40: VLT-BER-003-BRA-G | B40: =_xlfn.XLOOKUP(A40,CATÁLOGO!$A$2:$A$846,CATÁLOGO!$B$2:$B$846,"FORA DO CATÁLOGO") -> BER003B42 | C40: 4 | D40: =_xlfn.XLOOKUP(A40,CATÁLOGO!$A$2:$A$846,CATÁLOGO!$E$2:$E$846,"FORA DO CATÁLOGO") -> Ativo | E40: ESTOQUE SIMULADO | F40: =SUMIFS('AVARIA ESTIMADA'!$H$18:$H$40,'AVARIA ESTIMADA'!$A$18:$A$40,A40) -> 0
A41: VLT-BER-003-BRA-GG | B41: =_xlfn.XLOOKUP(A41,CATÁLOGO!$A$2:$A$846,CATÁLOGO!$B$2:$B$846,"FORA DO CATÁLOGO") -> BER003B44 | C41: 4 | D41: =_xlfn.XLOOKUP(A41,CATÁLOGO!$A$2:$A$846,CATÁLOGO!$E$2:$E$846,"FORA DO CATÁLOGO") -> Ativo | E41: ESTOQUE SIMULADO | F41: =SUMIFS('AVARIA ESTIMADA'!$H$18:$H$40,'AVARIA ESTIMADA'!$A$18:$A$40,A41) -> 0
A42: VLT-BER-003-BRA-XG | B42: =_xlfn.XLOOKUP(A42,CATÁLOGO!$A$2:$A$846,CATÁLOGO!$B$2:$B$846,"FORA DO CATÁLOGO") -> BER003B46 | C42: 1 | D42: =_xlfn.XLOOKUP(A42,CATÁLOGO!$A$2:$A$846,CATÁLOGO!$E$2:$E$846,"FORA DO CATÁLOGO") -> Ativo | E42: ESTOQUE SIMULADO | F42: =SUMIFS('AVARIA ESTIMADA'!$H$18:$H$40,'AVARIA ESTIMADA'!$A$18:$A$40,A42) -> 0
A43: VLT-ACE-003-BEG-U | B43: =_xlfn.XLOOKUP(A43,CATÁLOGO!$A$2:$A$846,CATÁLOGO!$B$2:$B$846,"FORA DO CATÁLOGO") -> ACE003GU | C43: 6 | D43: =_xlfn.XLOOKUP(A43,CATÁLOGO!$A$2:$A$846,CATÁLOGO!$E$2:$E$846,"FORA DO CATÁLOGO") -> Ativo | E43: ESTOQUE SIMULADO | F43: =SUMIFS('AVARIA ESTIMADA'!$H$18:$H$40,'AVARIA ESTIMADA'!$A$18:$A$40,A43) -> 0
A44: VLT-CAM-001-CIN-P | B44: =_xlfn.XLOOKUP(A44,CATÁLOGO!$A$2:$A$846,CATÁLOGO!$B$2:$B$846,"FORA DO CATÁLOGO") -> CAM001CP | C44: 6 | D44: =_xlfn.XLOOKUP(A44,CATÁLOGO!$A$2:$A$846,CATÁLOGO!$E$2:$E$846,"FORA DO CATÁLOGO") -> Ativo | E44: ESTOQUE SIMULADO | F44: =SUMIFS('AVARIA ESTIMADA'!$H$18:$H$40,'AVARIA ESTIMADA'!$A$18:$A$40,A44) -> 0
A45: VLT-CAM-001-CIN-M | B45: =_xlfn.XLOOKUP(A45,CATÁLOGO!$A$2:$A$846,CATÁLOGO!$B$2:$B$846,"FORA DO CATÁLOGO") -> CAM001CM | C45: 6 | D45: =_xlfn.XLOOKUP(A45,CATÁLOGO!$A$2:$A$846,CATÁLOGO!$E$2:$E$846,"FORA DO CATÁLOGO") -> Ativo | E45: ESTOQUE SIMULADO | F45: =SUMIFS('AVARIA ESTIMADA'!$H$18:$H$40,'AVARIA ESTIMADA'!$A$18:$A$40,A45) -> 0
... A720: VLT-ACE-007-BEG-U | B720: =_xlfn.XLOOKUP(A720,CATÁLOGO!$A$2:$A$846,CATÁLOGO!$B$2:$B$846,"FORA DO CATÁLOGO") -> ACE007GU | C720: 5 | D720: =_xlfn.XLOOKUP(A720,CATÁLOGO!$A$2:$A$846,CATÁLOGO!$E$2:$E$846,"FORA DO CATÁLOGO") -> Descontinuado | E720: ESTOQUE SIMULADO | F720: =SUMIFS('AVARIA ESTIMADA'!$H$18:$H$40,'AVARIA ESTIMADA'!$A$18:$A$40,A720) -> 0

Sheet BATEL
A1: SKU | B1: CÓDIGO CD | C1: QTD | D1: STATUS CATÁLOGO | E1: OBS | F1: AVARIA EST. | H1: RESUMO AVARIA – BATEL
A2: VLT-CAL-001-OLI-P | B2: =_xlfn.XLOOKUP(A2,CATÁLOGO!$A$2:$A$846,CATÁLOGO!$B$2:$B$846,"FORA DO CATÁLOGO") -> CAL001V38 | C2: 1 | D2: =_xlfn.XLOOKUP(A2,CATÁLOGO!$A$2:$A$846,CATÁLOGO!$E$2:$E$846,"FORA DO CATÁLOGO") -> Fora do catálogo 2026 | E2: faltou contar provador | provador considerado 0 (decisão 15/10) | F2: =SUMIFS('AVARIA ESTIMADA'!$J$18:$J$40,'AVARIA ESTIMADA'!$A$18:$A$40,A2) -> 0 | H2: Tipo de avaria | I2: Estimada (decisão 13)
A3: VLT-CAL-001-VIN-XP | B3: =_xlfn.XLOOKUP(A3,CATÁLOGO!$A$2:$A$846,CATÁLOGO!$B$2:$B$846,"FORA DO CATÁLOGO") -> CAL001H36 | C3: 2 | D3: =_xlfn.XLOOKUP(A3,CATÁLOGO!$A$2:$A$846,CATÁLOGO!$E$2:$E$846,"FORA DO CATÁLOGO") -> Fora do catálogo 2026 | F3: =SUMIFS('AVARIA ESTIMADA'!$J$18:$J$40,'AVARIA ESTIMADA'!$A$18:$A$40,A3) -> 0 | H3: Estoque contado (inclui avaria) | I3: =SUM(C2:C721) -> 1904
A4: VLT-CAL-001-VIN-P | B4: =_xlfn.XLOOKUP(A4,CATÁLOGO!$A$2:$A$846,CATÁLOGO!$B$2:$B$846,"FORA DO CATÁLOGO") -> CAL001H38 | C4: 1 | D4: =_xlfn.XLOOKUP(A4,CATÁLOGO!$A$2:$A$846,CATÁLOGO!$E$2:$E$846,"FORA DO CATÁLOGO") -> Fora do catálogo 2026 | F4: =SUMIFS('AVARIA ESTIMADA'!$J$18:$J$40,'AVARIA ESTIMADA'!$A$18:$A$40,A4) -> 0 | H4: Peças com avaria | I4: =SUM(F2:F721) -> 49
A5: VLT-CAL-001-VIN-GG | B5: =_xlfn.XLOOKUP(A5,CATÁLOGO!$A$2:$A$846,CATÁLOGO!$B$2:$B$846,"FORA DO CATÁLOGO") -> CAL001H44 | C5: 1 | D5: =_xlfn.XLOOKUP(A5,CATÁLOGO!$A$2:$A$846,CATÁLOGO!$E$2:$E$846,"FORA DO CATÁLOGO") -> Fora do catálogo 2026 | F5: =SUMIFS('AVARIA ESTIMADA'!$J$18:$J$40,'AVARIA ESTIMADA'!$A$18:$A$40,A5) -> 0 | H5: Estoque vendável | I5: =I3-I4 -> 1855
A6: VLT-TRI-003-BEG-G | B6: =_xlfn.XLOOKUP(A6,CATÁLOGO!$A$2:$A$846,CATÁLOGO!$B$2:$B$846,"FORA DO CATÁLOGO") -> TRI003GG | C6: 1 | D6: =_xlfn.XLOOKUP(A6,CATÁLOGO!$A$2:$A$846,CATÁLOGO!$E$2:$E$846,"FORA DO CATÁLOGO") -> Fora do catálogo 2026 | F6: =SUMIFS('AVARIA ESTIMADA'!$J$18:$J$40,'AVARIA ESTIMADA'!$A$18:$A$40,A6) -> 0 | H6: % avaria | I6: =I4/I3 -> 0.025735294
A7: VLT-TRI-003-MRR-G | B7: =_xlfn.XLOOKUP(A7,CATÁLOGO!$A$2:$A$846,CATÁLOGO!$B$2:$B$846,"FORA DO CATÁLOGO") -> TRI003MG | C7: 1 | D7: =_xlfn.XLOOKUP(A7,CATÁLOGO!$A$2:$A$846,CATÁLOGO!$E$2:$E$846,"FORA DO CATÁLOGO") -> Fora do catálogo 2026 | F7: =SUMIFS('AVARIA ESTIMADA'!$J$18:$J$40,'AVARIA ESTIMADA'!$A$18:$A$40,A7) -> 0 | H7: SKUs afetados | I7: =COUNTIF(F2:F721,">0") -> 20
A8: VLT-SAI-001-PRE-GG | B8: =_xlfn.XLOOKUP(A8,CATÁLOGO!$A$2:$A$846,CATÁLOGO!$B$2:$B$846,"FORA DO CATÁLOGO") -> SAI001PGG | C8: 1 | D8: =_xlfn.XLOOKUP(A8,CATÁLOGO!$A$2:$A$846,CATÁLOGO!$E$2:$E$846,"FORA DO CATÁLOGO") -> Fora do catálogo 2026 | F8: =SUMIFS('AVARIA ESTIMADA'!$J$18:$J$40,'AVARIA ESTIMADA'!$A$18:$A$40,A8) -> 0 | H8: % avaria – média das 4 lojas | I8: ='AVARIA ESTIMADA'!F14 -> 0.029957854
A9: VLT-SAI-001-BEG-GG | B9: =_xlfn.XLOOKUP(A9,CATÁLOGO!$A$2:$A$846,CATÁLOGO!$B$2:$B$846,"FORA DO CATÁLOGO") -> SAI001GGG | C9: 1 | D9: =_xlfn.XLOOKUP(A9,CATÁLOGO!$A$2:$A$846,CATÁLOGO!$E$2:$E$846,"FORA DO CATÁLOGO") -> Fora do catálogo 2026 | F9: =SUMIFS('AVARIA ESTIMADA'!$J$18:$J$40,'AVARIA ESTIMADA'!$A$18:$A$40,A9) -> 0
A10: VLT-BER-001-BRA-M | B10: =_xlfn.XLOOKUP(A10,CATÁLOGO!$A$2:$A$846,CATÁLOGO!$B$2:$B$846,"FORA DO CATÁLOGO") -> BER001B40 | C10: 6 | D10: =_xlfn.XLOOKUP(A10,CATÁLOGO!$A$2:$A$846,CATÁLOGO!$E$2:$E$846,"FORA DO CATÁLOGO") -> Ativo | E10: faltou contar provador | provador considerado 0 (decisão 15/10) | F10: =SUMIFS('AVARIA ESTIMADA'!$J$18:$J$40,'AVARIA ESTIMADA'!$A$18:$A$40,A10) -> 0 | H10: SKUs com avaria (maior → menor)
A11: VLT-BER-001-BRA-G | B11: =_xlfn.XLOOKUP(A11,CATÁLOGO!$A$2:$A$846,CATÁLOGO!$B$2:$B$846,"FORA DO CATÁLOGO") -> BER001B42 | C11: 4 | D11: =_xlfn.XLOOKUP(A11,CATÁLOGO!$A$2:$A$846,CATÁLOGO!$E$2:$E$846,"FORA DO CATÁLOGO") -> Ativo | F11: =SUMIFS('AVARIA ESTIMADA'!$J$18:$J$40,'AVARIA ESTIMADA'!$A$18:$A$40,A11) -> 0 | H11: SKU | I11: PEÇAS
A12: VLT-BER-001-BRA-GG | B12: =_xlfn.XLOOKUP(A12,CATÁLOGO!$A$2:$A$846,CATÁLOGO!$B$2:$B$846,"FORA DO CATÁLOGO") -> BER001B44 | C12: 3 | D12: =_xlfn.XLOOKUP(A12,CATÁLOGO!$A$2:$A$846,CATÁLOGO!$E$2:$E$846,"FORA DO CATÁLOGO") -> Ativo | F12: =SUMIFS('AVARIA ESTIMADA'!$J$18:$J$40,'AVARIA ESTIMADA'!$A$18:$A$40,A12) -> 0 | H12: {=_xlfn._xlws.SORT(_xlfn._xlws.FILTER(_xlfn.HSTACK(A2:A721,F2:F721),F2:F721>0,"sem avaria"),2,-1)} -> VLT-CAL-023-LIL-M | I12: 5
A13: VLT-CAL-003-PRE-P | B13: =_xlfn.XLOOKUP(A13,CATÁLOGO!$A$2:$A$846,CATÁLOGO!$B$2:$B$846,"FORA DO CATÁLOGO") -> CAL003P38 | C13: 6 | D13: =_xlfn.XLOOKUP(A13,CATÁLOGO!$A$2:$A$846,CATÁLOGO!$E$2:$E$846,"FORA DO CATÁLOGO") -> Ativo | E13: recontar | QTD imputada pela mediana Pinheiros/Eldorado (contado: 5; decisão 15/10) | F13: =SUMIFS('AVARIA ESTIMADA'!$J$18:$J$40,'AVARIA ESTIMADA'!$A$18:$A$40,A13) -> 0 | H13: VLT-CAL-003-PRE-G | I13: 4
A14: VLT-CAL-003-PRE-M | B14: =_xlfn.XLOOKUP(A14,CATÁLOGO!$A$2:$A$846,CATÁLOGO!$B$2:$B$846,"FORA DO CATÁLOGO") -> CAL003P40 | C14: 5 | D14: =_xlfn.XLOOKUP(A14,CATÁLOGO!$A$2:$A$846,CATÁLOGO!$E$2:$E$846,"FORA DO CATÁLOGO") -> Ativo | F14: =SUMIFS('AVARIA ESTIMADA'!$J$18:$J$40,'AVARIA ESTIMADA'!$A$18:$A$40,A14) -> 0 | H14: VLT-CAL-011-LIL-P | I14: 4
A15: VLT-CAL-003-PRE-G | B15: =_xlfn.XLOOKUP(A15,CATÁLOGO!$A$2:$A$846,CATÁLOGO!$B$2:$B$846,"FORA DO CATÁLOGO") -> CAL003P42 | C15: 4 | D15: =_xlfn.XLOOKUP(A15,CATÁLOGO!$A$2:$A$846,CATÁLOGO!$E$2:$E$846,"FORA DO CATÁLOGO") -> Ativo | F15: =SUMIFS('AVARIA ESTIMADA'!$J$18:$J$40,'AVARIA ESTIMADA'!$A$18:$A$40,A15) -> 4 | H15: VLT-CAL-024-AZM-P | I15: 4
A16: VLT-CAL-003-PRE-GG | B16: =_xlfn.XLOOKUP(A16,CATÁLOGO!$A$2:$A$846,CATÁLOGO!$B$2:$B$846,"FORA DO CATÁLOGO") -> CAL003P44 | C16: 2 | D16: =_xlfn.XLOOKUP(A16,CATÁLOGO!$A$2:$A$846,CATÁLOGO!$E$2:$E$846,"FORA DO CATÁLOGO") -> Ativo | F16: =SUMIFS('AVARIA ESTIMADA'!$J$18:$J$40,'AVARIA ESTIMADA'!$A$18:$A$40,A16) -> 0 | H16: VLT-TOP-001-AMA-G | I16: 4
A17: VLT-CAL-004-CIN-XP | B17: =_xlfn.XLOOKUP(A17,CATÁLOGO!$A$2:$A$846,CATÁLOGO!$B$2:$B$846,"FORA DO CATÁLOGO") -> CAL004C36 | C17: 1 | D17: =_xlfn.XLOOKUP(A17,CATÁLOGO!$A$2:$A$846,CATÁLOGO!$E$2:$E$846,"FORA DO CATÁLOGO") -> Ativo | F17: =SUMIFS('AVARIA ESTIMADA'!$J$18:$J$40,'AVARIA ESTIMADA'!$A$18:$A$40,A17) -> 0 | H17: VLT-TOP-006-MRR-G | I17: 3
A18: VLT-CAL-004-CIN-P | B18: =_xlfn.XLOOKUP(A18,CATÁLOGO!$A$2:$A$846,CATÁLOGO!$B$2:$B$846,"FORA DO CATÁLOGO") -> CAL004C38 | C18: 1 | D18: =_xlfn.XLOOKUP(A18,CATÁLOGO!$A$2:$A$846,CATÁLOGO!$E$2:$E$846,"FORA DO CATÁLOGO") -> Ativo | F18: =SUMIFS('AVARIA ESTIMADA'!$J$18:$J$40,'AVARIA ESTIMADA'!$A$18:$A$40,A18) -> 0 | H18: VLT-VES-006-MRR-G | I18: 3
A19: VLT-CAL-004-CIN-M | B19: =_xlfn.XLOOKUP(A19,CATÁLOGO!$A$2:$A$846,CATÁLOGO!$B$2:$B$846,"FORA DO CATÁLOGO") -> CAL004C40 | C19: 3 | D19: =_xlfn.XLOOKUP(A19,CATÁLOGO!$A$2:$A$846,CATÁLOGO!$E$2:$E$846,"FORA DO CATÁLOGO") -> Ativo | F19: =SUMIFS('AVARIA ESTIMADA'!$J$18:$J$40,'AVARIA ESTIMADA'!$A$18:$A$40,A19) -> 0 | H19: VLT-CAM-017-AMA-G | I19: 3
A20: VLT-CAL-004-CIN-G | B20: =_xlfn.XLOOKUP(A20,CATÁLOGO!$A$2:$A$846,CATÁLOGO!$B$2:$B$846,"FORA DO CATÁLOGO") -> CAL004C42 | C20: 1 | D20: =_xlfn.XLOOKUP(A20,CATÁLOGO!$A$2:$A$846,CATÁLOGO!$E$2:$E$846,"FORA DO CATÁLOGO") -> Ativo | E20: faltou contar provador | provador considerado 0 (decisão 15/10) | F20: =SUMIFS('AVARIA ESTIMADA'!$J$18:$J$40,'AVARIA ESTIMADA'!$A$18:$A$40,A20) -> 0 | H20: VLT-CAM-020-AMA-G | I20: 3
A21: VLT-CAL-004-CIN-GG | B21: =_xlfn.XLOOKUP(A21,CATÁLOGO!$A$2:$A$846,CATÁLOGO!$B$2:$B$846,"FORA DO CATÁLOGO") -> CAL004C44 | C21: 1 | D21: =_xlfn.XLOOKUP(A21,CATÁLOGO!$A$2:$A$846,CATÁLOGO!$E$2:$E$846,"FORA DO CATÁLOGO") -> Ativo | F21: =SUMIFS('AVARIA ESTIMADA'!$J$18:$J$40,'AVARIA ESTIMADA'!$A$18:$A$40,A21) -> 0 | H21: VLT-CAM-004-PRE-M | I21: 2
A22: VLT-CAL-004-CIN-XG | B22: =_xlfn.XLOOKUP(A22,CATÁLOGO!$A$2:$A$846,CATÁLOGO!$B$2:$B$846,"FORA DO CATÁLOGO") -> CAL004C46 | C22: 1 | D22: =_xlfn.XLOOKUP(A22,CATÁLOGO!$A$2:$A$846,CATÁLOGO!$E$2:$E$846,"FORA DO CATÁLOGO") -> Ativo | E22: faltou contar provador | provador considerado 0 (decisão 15/10) | F22: =SUMIFS('AVARIA ESTIMADA'!$J$18:$J$40,'AVARIA ESTIMADA'!$A$18:$A$40,A22) -> 0 | H22: VLT-VES-007-OLI-GG | I22: 2
A23: VLT-CAL-004-BEG-XP | B23: =_xlfn.XLOOKUP(A23,CATÁLOGO!$A$2:$A$846,CATÁLOGO!$B$2:$B$846,"FORA DO CATÁLOGO") -> CAL004G36 | C23: 1 | D23: =_xlfn.XLOOKUP(A23,CATÁLOGO!$A$2:$A$846,CATÁLOGO!$E$2:$E$846,"FORA DO CATÁLOGO") -> Ativo | F23: =SUMIFS('AVARIA ESTIMADA'!$J$18:$J$40,'AVARIA ESTIMADA'!$A$18:$A$40,A23) -> 0 | H23: VLT-CAL-016-OLI-P | I23: 2
A24: VLT-CAL-004-BEG-P | B24: =_xlfn.XLOOKUP(A24,CATÁLOGO!$A$2:$A$846,CATÁLOGO!$B$2:$B$846,"FORA DO CATÁLOGO") -> CAL004G38 | C24: 1 | D24: =_xlfn.XLOOKUP(A24,CATÁLOGO!$A$2:$A$846,CATÁLOGO!$E$2:$E$846,"FORA DO CATÁLOGO") -> Ativo | F24: =SUMIFS('AVARIA ESTIMADA'!$J$18:$J$40,'AVARIA ESTIMADA'!$A$18:$A$40,A24) -> 0 | H24: VLT-BER-007-AZM-G | I24: 2
A25: VLT-CAL-004-BEG-G | B25: =_xlfn.XLOOKUP(A25,CATÁLOGO!$A$2:$A$846,CATÁLOGO!$B$2:$B$846,"FORA DO CATÁLOGO") -> CAL004G42 | C25: 1 | D25: =_xlfn.XLOOKUP(A25,CATÁLOGO!$A$2:$A$846,CATÁLOGO!$E$2:$E$846,"FORA DO CATÁLOGO") -> Ativo | E25: recontar | QTD imputada pela mediana Pinheiros/Eldorado (contado: 1; decisão 15/10) | F25: =SUMIFS('AVARIA ESTIMADA'!$J$18:$J$40,'AVARIA ESTIMADA'!$A$18:$A$40,A25) -> 0 | H25: VLT-VES-009-BEG-G | I25: 2
A26: VLT-CAL-004-BEG-GG | B26: =_xlfn.XLOOKUP(A26,CATÁLOGO!$A$2:$A$846,CATÁLOGO!$B$2:$B$846,"FORA DO CATÁLOGO") -> CAL004G44 | C26: 1 | D26: =_xlfn.XLOOKUP(A26,CATÁLOGO!$A$2:$A$846,CATÁLOGO!$E$2:$E$846,"FORA DO CATÁLOGO") -> Ativo | F26: =SUMIFS('AVARIA ESTIMADA'!$J$18:$J$40,'AVARIA ESTIMADA'!$A$18:$A$40,A26) -> 0 | H26: VLT-MOL-008-VIN-GG | I26: 1
A27: VLT-CAL-004-BEG-XG | B27: =_xlfn.XLOOKUP(A27,CATÁLOGO!$A$2:$A$846,CATÁLOGO!$B$2:$B$846,"FORA DO CATÁLOGO") -> CAL004G46 | C27: 1 | D27: =_xlfn.XLOOKUP(A27,CATÁLOGO!$A$2:$A$846,CATÁLOGO!$E$2:$E$846,"FORA DO CATÁLOGO") -> Ativo | F27: =SUMIFS('AVARIA ESTIMADA'!$J$18:$J$40,'AVARIA ESTIMADA'!$A$18:$A$40,A27) -> 0 | H27: VLT-TOP-010-AMA-M | I27: 1
A28: VLT-CAL-005-PRE-XP | B28: =_xlfn.XLOOKUP(A28,CATÁLOGO!$A$2:$A$846,CATÁLOGO!$B$2:$B$846,"FORA DO CATÁLOGO") -> CAL005P36 | C28: 3 | D28: =_xlfn.XLOOKUP(A28,CATÁLOGO!$A$2:$A$846,CATÁLOGO!$E$2:$E$846,"FORA DO CATÁLOGO") -> Ativo | F28: =SUMIFS('AVARIA ESTIMADA'!$J$18:$J$40,'AVARIA ESTIMADA'!$A$18:$A$40,A28) -> 0 | H28: VLT-BER-006-LIL-G | I28: 1
A29: VLT-CAL-005-PRE-P | B29: =_xlfn.XLOOKUP(A29,CATÁLOGO!$A$2:$A$846,CATÁLOGO!$B$2:$B$846,"FORA DO CATÁLOGO") -> CAL005P38 | C29: 5 | D29: =_xlfn.XLOOKUP(A29,CATÁLOGO!$A$2:$A$846,CATÁLOGO!$E$2:$E$846,"FORA DO CATÁLOGO") -> Ativo | F29: =SUMIFS('AVARIA ESTIMADA'!$J$18:$J$40,'AVARIA ESTIMADA'!$A$18:$A$40,A29) -> 0 | H29: VLT-CAL-016-OLI-M | I29: 1
A30: VLT-CAL-005-PRE-M | B30: =_xlfn.XLOOKUP(A30,CATÁLOGO!$A$2:$A$846,CATÁLOGO!$B$2:$B$846,"FORA DO CATÁLOGO") -> CAL005P40 | C30: 6 | D30: =_xlfn.XLOOKUP(A30,CATÁLOGO!$A$2:$A$846,CATÁLOGO!$E$2:$E$846,"FORA DO CATÁLOGO") -> Ativo | F30: =SUMIFS('AVARIA ESTIMADA'!$J$18:$J$40,'AVARIA ESTIMADA'!$A$18:$A$40,A30) -> 0 | H30: VLT-SAI-009-BRA-P | I30: 1
A31: VLT-CAL-005-PRE-G | B31: =_xlfn.XLOOKUP(A31,CATÁLOGO!$A$2:$A$846,CATÁLOGO!$B$2:$B$846,"FORA DO CATÁLOGO") -> CAL005P42 | C31: 4 | D31: =_xlfn.XLOOKUP(A31,CATÁLOGO!$A$2:$A$846,CATÁLOGO!$E$2:$E$846,"FORA DO CATÁLOGO") -> Ativo | F31: =SUMIFS('AVARIA ESTIMADA'!$J$18:$J$40,'AVARIA ESTIMADA'!$A$18:$A$40,A31) -> 0 | H31: VLT-MOL-019-OLI-GG | I31: 1
A32: VLT-CAL-005-PRE-GG | B32: =_xlfn.XLOOKUP(A32,CATÁLOGO!$A$2:$A$846,CATÁLOGO!$B$2:$B$846,"FORA DO CATÁLOGO") -> CAL005P44 | C32: 3 | D32: =_xlfn.XLOOKUP(A32,CATÁLOGO!$A$2:$A$846,CATÁLOGO!$E$2:$E$846,"FORA DO CATÁLOGO") -> Ativo | F32: =SUMIFS('AVARIA ESTIMADA'!$J$18:$J$40,'AVARIA ESTIMADA'!$A$18:$A$40,A32) -> 0
A33: VLT-TOP-002-AZM-P | B33: =_xlfn.XLOOKUP(A33,CATÁLOGO!$A$2:$A$846,CATÁLOGO!$B$2:$B$846,"FORA DO CATÁLOGO") -> TOP002AP | C33: 3 | D33: =_xlfn.XLOOKUP(A33,CATÁLOGO!$A$2:$A$846,CATÁLOGO!$E$2:$E$846,"FORA DO CATÁLOGO") -> Ativo | F33: =SUMIFS('AVARIA ESTIMADA'!$J$18:$J$40,'AVARIA ESTIMADA'!$A$18:$A$40,A33) -> 0
A34: VLT-TOP-002-AZM-M | B34: =_xlfn.XLOOKUP(A34,CATÁLOGO!$A$2:$A$846,CATÁLOGO!$B$2:$B$846,"FORA DO CATÁLOGO") -> TOP002AM | C34: 2 | D34: =_xlfn.XLOOKUP(A34,CATÁLOGO!$A$2:$A$846,CATÁLOGO!$E$2:$E$846,"FORA DO CATÁLOGO") -> Ativo | F34: =SUMIFS('AVARIA ESTIMADA'!$J$18:$J$40,'AVARIA ESTIMADA'!$A$18:$A$40,A34) -> 0
A35: VLT-TOP-002-AZM-G | B35: =_xlfn.XLOOKUP(A35,CATÁLOGO!$A$2:$A$846,CATÁLOGO!$B$2:$B$846,"FORA DO CATÁLOGO") -> TOP002AG | C35: 4 | D35: =_xlfn.XLOOKUP(A35,CATÁLOGO!$A$2:$A$846,CATÁLOGO!$E$2:$E$846,"FORA DO CATÁLOGO") -> Ativo | F35: =SUMIFS('AVARIA ESTIMADA'!$J$18:$J$40,'AVARIA ESTIMADA'!$A$18:$A$40,A35) -> 0
A36: VLT-TOP-002-AZM-GG | B36: =_xlfn.XLOOKUP(A36,CATÁLOGO!$A$2:$A$846,CATÁLOGO!$B$2:$B$846,"FORA DO CATÁLOGO") -> TOP002AGG | C36: 2 | D36: =_xlfn.XLOOKUP(A36,CATÁLOGO!$A$2:$A$846,CATÁLOGO!$E$2:$E$846,"FORA DO CATÁLOGO") -> Ativo | F36: =SUMIFS('AVARIA ESTIMADA'!$J$18:$J$40,'AVARIA ESTIMADA'!$A$18:$A$40,A36) -> 0
A37: VLT-BER-002-CIN-XP | B37: =_xlfn.XLOOKUP(A37,CATÁLOGO!$A$2:$A$846,CATÁLOGO!$B$2:$B$846,"FORA DO CATÁLOGO") -> BER002C36 | C37: 1 | D37: =_xlfn.XLOOKUP(A37,CATÁLOGO!$A$2:$A$846,CATÁLOGO!$E$2:$E$846,"FORA DO CATÁLOGO") -> Ativo | F37: =SUMIFS('AVARIA ESTIMADA'!$J$18:$J$40,'AVARIA ESTIMADA'!$A$18:$A$40,A37) -> 0
A38: VLT-BER-002-CIN-P | B38: =_xlfn.XLOOKUP(A38,CATÁLOGO!$A$2:$A$846,CATÁLOGO!$B$2:$B$846,"FORA DO CATÁLOGO") -> BER002C38 | C38: 2 | D38: =_xlfn.XLOOKUP(A38,CATÁLOGO!$A$2:$A$846,CATÁLOGO!$E$2:$E$846,"FORA DO CATÁLOGO") -> Ativo | F38: =SUMIFS('AVARIA ESTIMADA'!$J$18:$J$40,'AVARIA ESTIMADA'!$A$18:$A$40,A38) -> 0
A39: VLT-BER-002-CIN-M | B39: =_xlfn.XLOOKUP(A39,CATÁLOGO!$A$2:$A$846,CATÁLOGO!$B$2:$B$846,"FORA DO CATÁLOGO") -> BER002C40 | C39: 2 | D39: =_xlfn.XLOOKUP(A39,CATÁLOGO!$A$2:$A$846,CATÁLOGO!$E$2:$E$846,"FORA DO CATÁLOGO") -> Ativo | F39: =SUMIFS('AVARIA ESTIMADA'!$J$18:$J$40,'AVARIA ESTIMADA'!$A$18:$A$40,A39) -> 0
A40: VLT-BER-002-CIN-G | B40: =_xlfn.XLOOKUP(A40,CATÁLOGO!$A$2:$A$846,CATÁLOGO!$B$2:$B$846,"FORA DO CATÁLOGO") -> BER002C42 | C40: 1 | D40: =_xlfn.XLOOKUP(A40,CATÁLOGO!$A$2:$A$846,CATÁLOGO!$E$2:$E$846,"FORA DO CATÁLOGO") -> Ativo | F40: =SUMIFS('AVARIA ESTIMADA'!$J$18:$J$40,'AVARIA ESTIMADA'!$A$18:$A$40,A40) -> 0
...

Sheet CD
A1: SKU | B1: CÓDIGO CD | C1: QTD | D1: QTD RESERVADA | E1: QTD DISPONÍVEL | F1: STATUS CATÁLOGO | G1: OBS
A2: VLT-BER-001-BRA-P | B2: =_xlfn.XLOOKUP(A2,CATÁLOGO!$A$2:$A$846,CATÁLOGO!$B$2:$B$846,"FORA DO CATÁLOGO") -> BER001B38 | C2: 6 | D2: 2 | E2: 4 | F2: =_xlfn.XLOOKUP(A2,CATÁLOGO!$A$2:$A$846,CATÁLOGO!$E$2:$E$846,"FORA DO CATÁLOGO") -> Ativo
A3: VLT-BER-001-BRA-M | B3: =_xlfn.XLOOKUP(A3,CATÁLOGO!$A$2:$A$846,CATÁLOGO!$B$2:$B$846,"FORA DO CATÁLOGO") -> BER001B40 | C3: 4 | D3: 0 | E3: 4 | F3: =_xlfn.XLOOKUP(A3,CATÁLOGO!$A$2:$A$846,CATÁLOGO!$E$2:$E$846,"FORA DO CATÁLOGO") -> Ativo
A4: VLT-BER-001-BRA-G | B4: =_xlfn.XLOOKUP(A4,CATÁLOGO!$A$2:$A$846,CATÁLOGO!$B$2:$B$846,"FORA DO CATÁLOGO") -> BER001B42 | C4: 2 | D4: 2 | E4: 0 | F4: =_xlfn.XLOOKUP(A4,CATÁLOGO!$A$2:$A$846,CATÁLOGO!$E$2:$E$846,"FORA DO CATÁLOGO") -> Ativo
A5: VLT-BER-001-BRA-GG | B5: =_xlfn.XLOOKUP(A5,CATÁLOGO!$A$2:$A$846,CATÁLOGO!$B$2:$B$846,"FORA DO CATÁLOGO") -> BER001B44 | C5: 4 | D5: 0 | E5: 4 | F5: =_xlfn.XLOOKUP(A5,CATÁLOGO!$A$2:$A$846,CATÁLOGO!$E$2:$E$846,"FORA DO CATÁLOGO") -> Ativo
A6: VLT-CAL-003-PRE-P | B6: =_xlfn.XLOOKUP(A6,CATÁLOGO!$A$2:$A$846,CATÁLOGO!$B$2:$B$846,"FORA DO CATÁLOGO") -> CAL003P38 | C6: 2 | D6: 0 | E6: 2 | F6: =_xlfn.XLOOKUP(A6,CATÁLOGO!$A$2:$A$846,CATÁLOGO!$E$2:$E$846,"FORA DO CATÁLOGO") -> Ativo
A7: VLT-CAL-003-PRE-M | B7: =_xlfn.XLOOKUP(A7,CATÁLOGO!$A$2:$A$846,CATÁLOGO!$B$2:$B$846,"FORA DO CATÁLOGO") -> CAL003P40 | C7: 10 | D7: 0 | E7: 10 | F7: =_xlfn.XLOOKUP(A7,CATÁLOGO!$A$2:$A$846,CATÁLOGO!$E$2:$E$846,"FORA DO CATÁLOGO") -> Ativo
A8: VLT-CAL-003-PRE-G | B8: =_xlfn.XLOOKUP(A8,CATÁLOGO!$A$2:$A$846,CATÁLOGO!$B$2:$B$846,"FORA DO CATÁLOGO") -> CAL003P42 | C8: 9 | D8: 0 | E8: 9 | F8: =_xlfn.XLOOKUP(A8,CATÁLOGO!$A$2:$A$846,CATÁLOGO!$E$2:$E$846,"FORA DO CATÁLOGO") -> Ativo
A9: VLT-CAL-003-PRE-GG | B9: =_xlfn.XLOOKUP(A9,CATÁLOGO!$A$2:$A$846,CATÁLOGO!$B$2:$B$846,"FORA DO CATÁLOGO") -> CAL003P44 | C9: 9 | D9: 0 | E9: 9 | F9: =_xlfn.XLOOKUP(A9,CATÁLOGO!$A$2:$A$846,CATÁLOGO!$E$2:$E$846,"FORA DO CATÁLOGO") -> Ativo
A10: VLT-CAL-004-CIN-XP | B10: =_xlfn.XLOOKUP(A10,CATÁLOGO!$A$2:$A$846,CATÁLOGO!$B$2:$B$846,"FORA DO CATÁLOGO") -> CAL004C36 | C10: 6 | D10: 0 | E10: 6 | F10: =_xlfn.XLOOKUP(A10,CATÁLOGO!$A$2:$A$846,CATÁLOGO!$E$2:$E$846,"FORA DO CATÁLOGO") -> Ativo
A11: VLT-CAL-004-CIN-P | B11: =_xlfn.XLOOKUP(A11,CATÁLOGO!$A$2:$A$846,CATÁLOGO!$B$2:$B$846,"FORA DO CATÁLOGO") -> CAL004C38 | C11: 3 | D11: 0 | E11: 3 | F11: =_xlfn.XLOOKUP(A11,CATÁLOGO!$A$2:$A$846,CATÁLOGO!$E$2:$E$846,"FORA DO CATÁLOGO") -> Ativo
A12: VLT-CAL-004-CIN-M | B12: =_xlfn.XLOOKUP(A12,CATÁLOGO!$A$2:$A$846,CATÁLOGO!$B$2:$B$846,"FORA DO CATÁLOGO") -> CAL004C40 | C12: 12 | D12: 2 | E12: 10 | F12: =_xlfn.XLOOKUP(A12,CATÁLOGO!$A$2:$A$846,CATÁLOGO!$E$2:$E$846,"FORA DO CATÁLOGO") -> Ativo
A13: VLT-CAL-004-CIN-G | B13: =_xlfn.XLOOKUP(A13,CATÁLOGO!$A$2:$A$846,CATÁLOGO!$B$2:$B$846,"FORA DO CATÁLOGO") -> CAL004C42 | C13: 6 | D13: 0 | E13: 6 | F13: =_xlfn.XLOOKUP(A13,CATÁLOGO!$A$2:$A$846,CATÁLOGO!$E$2:$E$846,"FORA DO CATÁLOGO") -> Ativo
... A604: VLT-JAQ-011-OLI-GG | B604: =_xlfn.XLOOKUP(A604,CATÁLOGO!$A$2:$A$846,CATÁLOGO!$B$2:$B$846,"FORA DO CATÁLOGO") -> JAQ011VGG | C604: 4 | D604: 0 | E604: 4 | F604: =_xlfn.XLOOKUP(A604,CATÁLOGO!$A$2:$A$846,CATÁLOGO!$E$2:$E$846,"FORA DO CATÁLOGO") -> Ativo

Sheet AVARIA PINHEIROS
